Workbook

Sheet SEM1
A4: Nom: | B4: BELIN brice
A5: semaine 1 | B5: du | C5: 46020 | D5: au | E5: =SUM(B50) -> 46026
E6: Route | F6: aller | G6: Client ou usine | I6: Client ou usine | K6: Route retour | M6: TOTAL | Q6: potentiel jour
A7: Jour | B7: Date | C7: Nom client ou usine | E7: Heure départ | F7: Heure arrivée | G7: Heure arrivée | H7: Heure départ | I7: Heure arrivée | J7: Heure départ | K7: Heure départ | L7: Heure arrivée | M7: Heure route | N7: Heure client | O7: Heure usine | P7: Général
A9: LUNDI | B9: =SUM(C5) -> 46020 | C9: CONDUCTIX OS172220 219867C001 | G9: 0.36388889 | H9: 0.52083333 | I9: 0.55208333 | J9: 0.70833333 | M9: =(F25-E25)+(L25-K25) -> 0 | N9: =(H9-G9) -> 0.15694444 | O9: =(J9-I9) -> 0.15625 | P9: =SUM(M9:O25) -> 0.31319444 | R9: CONDUCTIX | S9: (2h00)
S10: Récuperer les images bmp du fichier de paramétrage | W10: In progress…
S11: Mettre à jour les DBIs
R12: OS172220 | S12: (1h00)
S13: ENI CORAL
S14: Envoyer l'email à ALSYMEX en partant du retour de Vincent Sicre (PM) | X14: ok.Done
R15: 219254C001 | S15: (1h00)
S16: PADAH
S17: Récuperer les photos du PMS & les mettre sur notre disques Backup | X17: ok.Done
R18: 219867C001 | S18: (3h30)
S19: MARSA
S20: Mettre le doc dans ARAS:
T21: PLC Cab. | U21: 24134C21986702 | W21: ok.Done | X21: ECN nr: | Y21: 1026671 | Z21: EN ATTENTE VALIDATION DOC CTRL
T22: CSA | U22: 24CSAC21986701 | W22: In progress… | X22: ECN nr: | Y22: 1026565 | Z22: EN ATTENTE VALIDATION DOC CTRL
U23: voir les commentaires du client du 18/12/2025
U24: En attente retour ALSYMEX | W24: In progress…
Q25: 0.29166667
A26: MARDI | B26: =SUM(B9+1) -> 46021 | C26: 219867C001 CONDUCTIX RA141931 | G26: 0.31875 | H26: 0.52083333 | I26: 0.5625 | J26: 0.69930556 | M26: =(F39-E39)+(L39-K39) -> 0 | N26: =(H26-G26) -> 0.20208333 | O26: =(J26-I26) -> 0.13680556 | P26: =SUM(M26:O39) -> 0.33888889 | R26: 219867C001 | S26: (4h00)
S27: MARSA
S28: Validation des plans BJs suite retour STAHL | W28: ok.Done
T29: not pour BE CS | W29: In progress…
U30: Retour des étiquettes des BJs sur 2 lignes - Accepté ou non?? | Z30: In progress…
U31: Retour des étiquettes tags client avec 10 caractères max. - Accepté ou non??
R32: CONDUCTIX | S32: (2h00)
S33: Recherche du fichier excel PROFIBUS FP | V33: pas trouvé
S34: Maj des DBIs si besoin | V34: ok.Done
T35: en attente retour de CONDUCTIX sur ref du kit PWM
R36: RA141931 | S36: (2h00)
S37: BOREYONG
S38: Problème de radio sur site suite à achat nouvelle | W38: In progress…
Q39: 0.29166667
A40: MERCREDI | B40: =SUM(B26+1) -> 46022 | C40: VACANCES | G40: 0 | H40: 0 | I40: 0 | J40: 0 | M40: =(F42-E42)+(L42-K42) -> 0 | N40: =(H40-G40) -> 0 | O40: =(J40-I40) -> 0 | P40: =SUM(M40:O42) -> 0
Q42: 0
A43: JEUDI | B43: =SUM(B40+1) -> 46023 | C43: VACANCES | G43: 0 | H43: 0 | I43: 0 | J43: 0 | M43: =(F45-E45)+(L45-K45) -> 0 | N43: =(H43-G43) -> 0 | O43: =(J43-I43) -> 0 | P43: =SUM(M43:O45) -> 0
Q45: 0
A46: VENDREDI | B46: =SUM(B43+1) -> 46024 | C46: VACANCES | G46: 0 | H46: 0 | I46: 0 | J46: 0 | M46: =(F48-E48)+(L48-K48) -> 0 | N46: =(H46-G46) -> 0 | O46: =(J46-I46) -> 0 | P46: =SUM(M46:O48) -> 0
...

Sheet SEM2
A4: Nom: | B4: BELIN brice
A5: semaine 2 | B5: du | C5: =SUM('SEM1'!B50+1) -> 46027 | D5: au | E5: =SUM(B112) -> 46033
E6: Route | F6: aller | G6: Client ou usine | I6: Client ou usine | K6: Route retour | M6: TOTAL | Q6: potentiel jour
A7: Jour | B7: Date | C7: Nom client ou usine | E7: Heure départ | F7: Heure arrivée | G7: Heure arrivée | H7: Heure départ | I7: Heure arrivée | J7: Heure départ | K7: Heure départ | L7: Heure arrivée | M7: Heure route | N7: Heure client | O7: Heure usine | P7: Général
A9: LUNDI | B9: =SUM(C5) -> 46027 | C9: 219254C001 OS172220 217147C001 RA141931 219867C001 Point equip | G9: 0.33819444 | H9: 0.52083333 | I9: 0.57291667 | J9: 0.73194444 | M9: =(F32-E32)+(L32-K32) -> 0 | N9: =(H9-G9) -> 0.18263889 | O9: =(J9-I9) -> 0.15902778 | P9: =SUM(M9:O32) -> 0.34166667 | R9: 219254C001 | S9: (1h00)
S10: PADAH
S11: Répondre à email d'ACTEMIUM | V11: ok.Done
R12: OS172220 | S12: (1h00)
S13: ENI CORAL
S14: Répondre à email d'ALSYMEX (Valentin Mayer) | W14: ok.Done
R15: 217147C001 | S15: (1h00)
S16: COIGN
S17: Lire email de Christelle sur les commentaires client à propos de la logique | X17: In progress…
T18: en attente retour de JCP sur la prise en compte du commentaire client ou non
R19: RA141931 | S19: (1h00)
S20: BOREYONG
S21: Lire la réponse du client | U21: ok.Done
S22: Répondre à email de ATS | U22: ok.Done
R23: 219867C001 | S23: (2h30)
S24: MARSA
S25: Validation des bjs avec JCP | V25: ok.Done
T26: Voir commentaires & faire maj des plans
S27: Maj des specs BJs | V27: In progress… | W27: ECN nr: | X27: 1026693
T28: Ajustement des longeurs des "Nameplates" en fct de la longueur de la boite
R29: Pt projets | S29: (1h00)
S30: Point équipe sur les projets | U30: ok.Done
Q32: 0.29166667
A33: MARDI | B33: =SUM(B9+1) -> 46028 | C33: 219867C001 220594C001 | G33: 0.3375 | H33: 0.52083333 | I33: 0.55208333 | J33: 0.75833333 | M33: =(F41-E41)+(L41-K41) -> 0 | N33: =(H33-G33) -> 0.18333333 | O33: =(J33-I33) -> 0.20625 | P33: =SUM(M33:O41) -> 0.38958333 | R33: 219867C001 | S33: (5h00)
S34: MARSA
S35: Maj des specs BJs | V35: In progress… | W35: ECN nr: | X35: 1026693
T36: Ajustement des longeurs des "Nameplates" en fct de la longueur de la boite
R37: 220594C001 | S37: (2h00)
S38: GOLAR HILLI
S39: Répondre à l'email de Laurent Rozier | V39: ok.Done
Q41: 0.29166667
A42: MERCREDI | B42: =SUM(B33+1) -> 46029 | C42: 219867C001 220267C001 221299C001 | G42: 0.30138889 | H42: 0.52083333 | I42: 0.56527778 | J42: 0.76736111 | M42: =(F55-E55)+(L55-K55) -> 0 | N42: =(H42-G42) -> 0.21944444 | O42: =(J42-I42) -> 0.20208333 | P42: =SUM(M42:O55) -> 0.42152778 | R42: 219867C001 | S42: (2h00)
S43: MARSA
S44: Maj des specs BJs | V44: ok.Done | W44: ECN nr: | X44: 1026693 | Y44: En attente validation JCP
T45: Ajustement des longeurs des "Nameplates" en fct de la longueur de la boite | Y45: ok.Done
T46: Mettre les specs sur ARAS | V46: ok.Done
...

Sheet SEM3
A4: Nom: | B4: BELIN brice
A5: semaine 3 | B5: du | C5: =SUM('SEM2'!B112+1) -> 46034 | D5: au | E5: =SUM(B93) -> 46040
E6: Route | F6: aller | G6: Client ou usine | I6: Client ou usine | K6: Route retour | M6: TOTAL | Q6: potentiel jour
A7: Jour | B7: Date | C7: Nom client ou usine | E7: Heure départ | F7: Heure arrivée | G7: Heure arrivée | H7: Heure départ | I7: Heure arrivée | J7: Heure départ | K7: Heure départ | L7: Heure arrivée | M7: Heure route | N7: Heure client | O7: Heure usine | P7: Général
A9: LUNDI | B9: =SUM(C5) -> 46034 | C9: 219867C001 | G9: 0.35833333 | H9: 0.52083333 | I9: 0.56944444 | J9: 0.73958333 | M9: =(F9-E9)+(L9-K9) -> 0 | N9: =(H9-G9) -> 0.1625 | O9: =(J9-I9) -> 0.17013889 | P9: =SUM(M9:O18) -> 0.33263889 | R9: 219867C001 | S9: (7h00)
S10: MARSA
S11: Réception de l'architecture envoyé par ALSYMEX
S12: Maj du plan ci-dessous:
T13: Archi | U13: 24CSAC21986701 | W13: ok.Done | X13: ECN nr: | Y13: 1026565 | Z13: EN ATTENTE VALIDATION DOC CTRL
S14: Edition du document ci-dessous:
T15: FAT Elec | U15: 24FATC21986701 | W15: In progress… | X15: ECN nr: | Y15: 1026839
U16: vérification du travail d'HALMI
Q18: 0.29166667
A19: MARDI | B19: =SUM(B9+1) -> 46035 | C19: 219867C001 CONDUCTIX 219254C001 220179C001 | G19: 0.33333333 | H19: 0.52083333 | I19: 0.55208333 | J19: 0.75 | M19: =(F19-E19)+(L19-K19) -> 0 | N19: =(H19-G19) -> 0.1875 | O19: =(J19-I19) -> 0.19791667 | P19: =SUM(M19:O41) -> 0.38541667 | R19: 219867C001 | S19: (3h00)
S20: MARSA
S21: Edition du document ci-dessous:
T22: FAT Elec | U22: 24FATC21986701 | W22: In progress… | X22: ECN nr: | Y22: 1026839
U23: prise en compte des commentaires client
U24: remplir la CRS
S25: Mettre le plan ci-dessous sur ARAS:
T26: LCP | U26: 24134C21986701 | W26: ok.Done | X26: ECN nr: | Y26: 1026884 | Z26: EN ATTENTE VALIDATION DOC CTRL
R28: CONDUCTIX | S28: (2h00)
S29: Répondre à l'email de Mme Orban | V29: ok.Done
S30: Réondre email de Sharad | V30: ok.Done
S31: Maj du DBI + création nouveaux PNs | V31: ok.Done
R32: 219254C001 | S32: (1h00)
S33: PADAH
S34: Envoyez email à ACE | V34: ok.Done
S35: Mettre le plan ci-dessous sur ARAS:
T36: HPU | U36: 24136C21925401 | W36: ok.Done | X36: ECN nr: | Y36: 1024272 | Z36: EN ATTENTE VALIDATION DOC CTRL
R37: 220179C001 | S37: (1h00)
S38: CAKASA
S39: Répondre email de C,BERGER (ALSYMEX) | V39: ok.Done
Q41: 0.29166667
A42: MERCREDI | B42: =SUM(B19+1) -> 46036 | C42: CONDUCTIX 219867C001 | G42: 0.29097222 | H42: 0.52083333 | I42: 0.55208333 | J42: 0.72916667 | M42: =(F42-E42)+(L42-K42) -> 0 | N42: =(H42-G42) -> 0.22986111 | O42: =(J42-I42) -> 0.17708333 | P42: =SUM(M42:O60) -> 0.40694444 | R42: CONDUCTIX | S42: (3h00)
S43: Edition du Power Point Camille sur affichage Jay | V43: ok.Done
T44: 5 diapos
R45: 219254C001 | S45: (1h00)
S46: PADAH
S47: Mettre le plan ci-dessous sur ARAS:
...

Sheet SEM4
A4: Nom: | B4: BELIN brice
A5: semaine 4 | B5: du | C5: =SUM('SEM3'!B93+1) -> 46041 | D5: au | E5: =SUM(B132) -> 46047
E6: Route | F6: aller | G6: Client ou usine | I6: Client ou usine | K6: Route retour | M6: TOTAL | Q6: potentiel jour
A7: Jour | B7: Date | C7: Nom client ou usine | E7: Heure départ | F7: Heure arrivée | G7: Heure arrivée | H7: Heure départ | I7: Heure arrivée | J7: Heure départ | K7: Heure départ | L7: Heure arrivée | M7: Heure route | N7: Heure client | O7: Heure usine | P7: Général
A9: LUNDI | B9: =SUM(C5) -> 46041 | C9: 220198C001 219867C001 219254C001 | G9: 0.3375 | H9: 0.52083333 | I9: 0.57291667 | J9: 0.73263889 | M9: =(F9-E9)+(L9-K9) -> 0 | N9: =(H9-G9) -> 0.18333333 | O9: =(J9-I9) -> 0.15972222 | P9: =SUM(M9:O39) -> 0.34305556 | R9: 220198C001 | S9: (2h00)
S10: SHELL AUSTRALIA
S11: Mettre les documents ci-dessous sur ARAS: | V11: ok.Done | W11: ECN nr: | X11: 1027006 | Y11: EN ATTENTE VALIDATION DOC CTRL
T12: PLC Cab. | U12: 3313412168502
T13: CLD | U13: 3303012168502
T14: ECD | U14: 3303012168501
T15: HPU Enclosure | U15: 3313612168501 | W15: ECN nr: | X15: 1027023 | Y15: EN ATTENTE VALIDATION DOC CTRL
R16: 219867C001 | S16: (2h00)
S17: MARSA
S18: Validation ECN TAG_LIST | U18: ok.Done | V18: ECN nr: | W18: 1026994 | X18: EN ATTENTE VALIDATION BE CS
S19: FAT Elec | T19: 24FATC21986701 | V19: ok.Done | W19: ECN nr: | X19: 1026839 | Y19: EN ATTENTE VALIDATION DOC CTRL
T20: faire les modification suvant commentaires Christelle
S21: Meeting avec Team
R22: 219254C001 | S22: (2h00)
S23: PADAH
S24: Maj des documents ci-dessous: | V24: In progress… | W24: ECN nr: | X24: 1025530 | Y24: EN ATTENTE VALIDATION DOC CTRL
T25: UCL | U25: LS_UCLC21925401 | W25: ok.Done
U26: envoyer en Rev2 + CRS accepté par client
T27: 24125 | U27: 24125C21925401 | W27: In progress…
U28: voir commentaires client
T29: SDE | U29: LS_SDEC21925401 | W29: In progress…
U30: remplir la CRS suite retour d'ACTEMIUM
R31: 220594C001 | S31: (1h00)
S32: GOLAR HILLI
S33: Envoyez numéro ECN à ALSYMEX | V33: In progress… | W33: ECN nr: | X33: 1027025
T34: Maj des plans ci-dessous
T35: LCP | U35: 2413415199801 | W35: Rev3 | X35: to | Y35: Rev4
T36: PLC Cab. | U36: 2413415199802 | W36: Rev4 | X36: to | Y36: Rev5
T37: ECD | U37: 2403015199801 | W37: Rev11 | X37: to | Y37: Rev12
Q39: 0.29166667
A40: MARDI | B40: =SUM(B9+1) -> 46042 | C40: 220198C001 CONDUCTIX 219867C001 219254C001 | G40: 0.32916667 | H40: 0.52083333 | I40: 0.55208333 | J40: 0.66666667 | M40: =(F40-E40)+(L40-K40) -> 0 | N40: =(H40-G40) -> 0.19166667 | O40: =(J40-I40) -> 0.11458333 | P40: =SUM(M40:O63) -> 0.30625 | R40: 220198C001 | S40: (1h00)
S41: SHELL AUSTRALIA
T42: HPU Enclosure | U42: 3313612168501 | W42: ECN nr: | X42: 1027023 | Y42: EN ATTENTE VALIDATION DOC CTRL
R43: CONDUCTIX | S43: (2h00)
S44: Maj des références manquantes | V44: In progress…
R45: 219867C001
...

Sheet SEM5
A4: Nom: | B4: BELIN brice
A5: semaine 5 | B5: du | C5: =SUM('SEM4'!B132+1) -> 46048 | D5: au | E5: =SUM(B102) -> 46054
E6: Route | F6: aller | G6: Client ou usine | I6: Client ou usine | K6: Route retour | M6: TOTAL | Q6: potentiel jour
A7: Jour | B7: Date | C7: Nom client ou usine | E7: Heure départ | F7: Heure arrivée | G7: Heure arrivée | H7: Heure départ | I7: Heure arrivée | J7: Heure départ | K7: Heure départ | L7: Heure arrivée | M7: Heure route | N7: Heure client | O7: Heure usine | P7: Général
A9: LUNDI | B9: =SUM(C5) -> 46048 | C9: 216956C001 221402C001 219867C001 Team Meeting 218979C001 | G9: 0.36597222 | H9: 0.52083333 | I9: 0.5625 | J9: 0.75138889 | M9: =(F29-E29)+(L29-K29) -> 0 | N9: =(H9-G9) -> 0.15486111 | O9: =(J9-I9) -> 0.18888889 | P9: =SUM(M9:O29) -> 0.34375 | R9: 216956C001 | S9: (1h00)
S10: LYONDELL
S11: Meeting avec ALSYMEX pour la futur FAT | V11: ok.Done
T12: FAT procédure / simulateur / modif programme / markups, etc…
S13: Mettre les plans "MARKUPS" dans le répertoire PDF du projet | W13: ok.Done
S14: Mettre la plan ci-dessous sur ARAS:
T15: SVA | U15: 24133C21695601 | W15: In progress… | X15: ECN nr: | Y15: 1026971
U16: en attente du source AutoCAD de la part d'ACE
R17: 221402C001 | S17: (2h00)
S18: MADINA
S19: Remplir la trame suivi de projet | V19: ok.Done
S20: Donner la codif pour les plans à Delphine | V20: ok.Done
R21: 219867C001 | S21: (1h00)
S22: MARSA
S23: Confirmer les réfrences ALSYMEX des gaines thermo à David LEFORT | X23: ok.Done
R24: Team Meeting | S24: (1h00)
S25: Meeting avec Team JCP / HSA / HLA | V25: ok.Done
R26: 218979C001 | S26: (1h00)
S27: GOLAR
S28: Préparation du fichier géomètre avec ALI | V28: ok.Done
Q29: 0.29166667
A30: MARDI | B30: =SUM(B9+1) -> 46049 | C30: 220594C001 219867C001 219254C001 | G30: 0.32777778 | H30: 0.52083333 | I30: 0.55208333 | J30: 0.76597222 | M30: =(F47-E47)+(L47-K47) -> 0 | N30: =(H30-G30) -> 0.19305556 | O30: =(J30-I30) -> 0.21388889 | P30: =SUM(M30:O47) -> 0.40694444 | R30: 220594C001 | S30: (1h00)
S31: GOLAR HILLI
S32: Renvoyer emails aux SSTR Elec & Hydrau pour date des documents, | X32: ok.Done
S33: Répondre email de Christelle | U33: ok.Done
R34: 219867C001 | S34: (1h00)
S35: MARSA
S36: Envoyer email à Mr MUSNIER pour confirmation liaison PDS/SAFIIS sur Archtecture PLC | Y36: ok.Done
R37: 219254C001 | S37: (5h00)
S38: PADAH
S39: Maj des document ci-dessous:
T40: UCL | U40: LS_UCLC21925401 | W40: ok.Done | X40: ECN nr: | Y40: 1027128 | Z40: EN ATTENTE VALIDATION DOC CTRL
T41: 24125 | U41: 24125C21925401 | W41: In progress… | X41: ECN nr: | Y41: 1025530 | Z41: EN ATTENTE MAJ BBE
U42: voir commentaires client
T43: SDE | U43: LS_SDEC21925401 | W43: ok.Done | X43: ECN nr: | Y43: 1025530 | Z43: DOCUMENT NON MIS A JOUR
U44: remplir la CRS suite retour d'ACTEMIUM | X44: ok.Done
...

Sheet SEM6
A4: Nom: | B4: BELIN brice
A5: semaine 6 | B5: du | C5: =SUM('SEM5'!B102+1) -> 46055 | D5: au | E5: =SUM(B109) -> 46061
E6: Route | F6: aller | G6: Client ou usine | I6: Client ou usine | K6: Route retour | M6: TOTAL | Q6: potentiel jour
A7: Jour | B7: Date | C7: Nom client ou usine | E7: Heure départ | F7: Heure arrivée | G7: Heure arrivée | H7: Heure départ | I7: Heure arrivée | J7: Heure départ | K7: Heure départ | L7: Heure arrivée | M7: Heure route | N7: Heure client | O7: Heure usine | P7: Général
A9: LUNDI | B9: =SUM(C5) -> 46055 | C9: 220224C001 216956C001 | G9: 0.34305556 | H9: 0.52083333 | I9: 0.5625 | J9: 0.65972222 | M9: =(F9-E9)+(L9-K9) -> 0 | N9: =(H9-G9) -> 0.17777778 | O9: =(J9-I9) -> 0.097222222 | P9: =SUM(M9:O21) -> 0.275 | R9: 220224C001 | S9: (1h00)
S10: ADNOC
S11: Réception des sources AutoCAD | V11: ok.Done
R12: 216956C001 | S12: (2h00)
S13: LYONDELL
S14: Edition du document ci-dessous:
T15: FAT ELEC | U15: LS_EFPC21695601 | W15: ok.Done | X15: EN ATTENTE RETOUR ALSYMEX
U16: Après retour ALSYMEX, envoyer la FAT au client
R17: 218979C001 | S17: (1h30)
S18: CIMC GOLAR
T19: Aide au YT | U19: ok.Done
Q21: 0.16666667
A22: MARDI | B22: =SUM(B9+1) -> 46056 | C22: RA172190 219254C001 216240C001 | G22: 0.34166667 | H22: 0.52083333 | I22: 0.55208333 | J22: 0.72638889 | M22: =(F22-E22)+(L22-K22) -> 0 | N22: =(H22-G22) -> 0.17916667 | O22: =(J22-I22) -> 0.17430556 | P22: =SUM(M22:O36) -> 0.35347222 | R22: RA172190 | S22: (1h00)
S23: HOEGH
S24: Maj du plan ci-dessous suite commentaire client:
T25: 2413617219001 | V25: ok.Done | W25: ECN nr: | X25: 1027354 | Y25: EN ATTENTE RETOUR ACE
R26: 219254C001 | S26: (2h00)
S27: PADAH
S28: Mah des documents ci-dessous:
T29: CND | U29: LS_CNDC21925401 | V29: ok.Done | W29: ECN nr: | X29: 1027379 | Y29: EN ATTENTE RETOUR JCP
R30: 216956C001 | S30: (1h00)
S31: LYONDELL
S32: Meeting avec Mr Garagon/Etienne (ALSYMEX) | V32: ok.Done
R33: 216240C001 | S33: (1h00)
S34: MOTOR OIL
S35: DR with BE Meca | V35: ok.Done
Q36: 0.29166667
A37: MERCREDI | B37: =SUM(B22+1) -> 46057 | C37: 220198C001 214365C001 218979C001 | G37: 0.32847222 | H37: 0.51041667 | I37: 0.56944444 | J37: 0.74930556 | M37: =(F37-E37)+(L37-K37) -> 0 | N37: =(H37-G37) -> 0.18194444 | O37: =(J37-I37) -> 0.17986111 | P37: =SUM(M37:O68) -> 0.36180556 | R37: 220198C001 | S37: (1h00)
S38: SHELL AUTRALIA
S39: Mettre le doc ci-dessous sur ARAS:
T40: PLC Listing | V40: In progress… | W40: Rev7 | X40: ECN nr: | Y40: 1027413 | Z40: EN ATTENTE VALIDATION JCP
T41: voir pour la page de garde client
R42: 214365C001 | S42: (1h00)
S43: TECNICAS REUNIDAS
S44: Meeting avec Volkan pour les documents ci-dessous: | V44: ok.Done
T45: ILD | U45: 24ILDC21436501 | V45: EN ATTENTE AJOUT PROJET DANS EXCEL SUR TEAMS - HSA
...

Sheet SEM7
A4: Nom: | B4: BELIN brice
A5: semaine 7 | B5: du | C5: =SUM('SEM6'!B109+1) -> 46062 | D5: au | E5: =SUM(B79) -> 46068
E6: Route | F6: aller | G6: Client ou usine | I6: Client ou usine | K6: Route retour | M6: TOTAL | Q6: potentiel jour
A7: Jour | B7: Date | C7: Nom client ou usine | E7: Heure départ | F7: Heure arrivée | G7: Heure arrivée | H7: Heure départ | I7: Heure arrivée | J7: Heure départ | K7: Heure départ | L7: Heure arrivée | M7: Heure route | N7: Heure client | O7: Heure usine | P7: Général
A9: LUNDI | B9: =SUM(C5) -> 46062 | C9: 219254C001 216956C001 217147C001 | G9: 0.32916667 | H9: 0.52083333 | I9: 0.56597222 | J9: 0.73680556 | M9: =(F9-E9) -> 0 | N9: =(H9-G9) -> 0.19166667 | O9: =(J9-I9) -> 0.17083333 | P9: =SUM(M9:O31) -> 0.3625 | R9: 219254C001 | S9: (3h00)
S10: PADAH LNG
S11: Maj des documents ci-dessous:
T12: EID | U12: 24EIDC21925401 | V12: ok.Done | W12: ECN nr: | X12: 1027491 | Y12: EN ATTENTE RETOUR D'INFORMATION SR
U13: maj suite commentaires client - REV4 IN PROGRESS
R14: 216956C001 | S14: (2h00)
S15: LYONDELL
S16: Mettre les plans ci-dessous sur ARAS: | W16: ok.Done | X16: ECN nr: | Y16: 1022242 | Z16: EN ATTENTE VALIDATION DOC CTRL (Delphine)
T17: IOL | U17: 24IOL12174001 | V17: Rev6
T18: ECD | U18: 2403012174001 | V18: Rev5
T19: CLD | U19: 2403012174002 | V19: Rev6
T20: Schéma boucles | U20: 2403112174002 | V20: Rev3
T21: TBWD | U21: 2403112174003 | V21: Rev5 | W21: Rev6 | X21: EN ATTENTE DOC REV6 ALSYMEX
T22: LCP | U22: 2413412174001 | V22: Rev7
R23: 217147C001 | S23: (1h00)
S24: COIGN
S25: Répondre à l'email d'ORLA
S26: Envoyer un email à ALSYMEX pour modification avec logique commenté par le client | Y26: ok.Done
R27: 216240C001 | S27: (1h00)
S28: MARSA
S29: Maj du document ci-dessous:
T30: Line List | U30: LS_PLLC21986701 | V30: In progress… | W30: EN ATTENTE RETOUR BE MECA & INDUS
Q31: 0.29166667
A32: MARDI | B32: =SUM(B9+1) -> 46063 | C32: 219867C001 217805C001 220267C001 | G32: 0.34652778 | H32: 0.52083333 | I32: 0.5625 | J32: 0.77430556 | M32: =(F49-E49)+(L49-K49) -> 0 | N32: =(H32-G32) -> 0.17430556 | O32: =(J32-I32) -> 0.21180556 | P32: =SUM(M32:O49) -> 0.38611111 | R32: 219867C001 | S32: (3h00)
S33: MARSA
S34: Maj du document ci-dessous:
T35: IOL | U35: LS_IOLC21986701 | V35: In progress… | W35: ECN nr: | X35: 1027541
R36: 217805C001 | S36: (3h00)
S37: FLUXEL
S38: Meeting Pascal M. pour explication du prog VDF | V38: ok.Done
S39: Edition de la trame de pour YT | V39: ok.Done
S40: Meeting Charly D / Pascal M / Stéphane P | V40: In progress…
R41: 220267C001 | S41: (1h00)
S42: RUWAIS
S43: Vérification des validation ECNs ci-dessous:
T44: 1027314 | V44: Validated
...

Sheet SEM8
A4: Nom: | B4: BELIN brice
A5: semaine 8 | B5: du | C5: =SUM('SEM7'!B79+1) -> 46069 | D5: au | E5: =SUM(B46) -> 46075
E6: Route | F6: aller | G6: Client ou usine | I6: Client ou usine | K6: Route retour | M6: TOTAL | Q6: potentiel jour
A7: Jour | B7: Date | C7: Nom client ou usine | E7: Heure départ | F7: Heure arrivée | G7: Heure arrivée | H7: Heure départ | I7: Heure arrivée | J7: Heure départ | K7: Heure départ | L7: Heure arrivée | M7: Heure route | N7: Heure client | O7: Heure usine | P7: Général
A9: LUNDI | B9: =SUM(C5) -> 46069 | C9: RTT | G9: 0 | H9: 0 | I9: 0 | J9: 0 | M9: =(F9-E9) -> 0 | N9: =(H9-G9) -> 0 | O9: =(J9-I9) -> 0 | P9: =SUM(M9:O12) -> 0
Q12: 0
A13: MARDI | B13: =SUM(B9+1) -> 46070 | C13: RTT | G13: 0 | H13: 0 | I13: 0 | J13: 0 | M13: =(F13-E13) -> 0 | N13: =(H13-G13) -> 0 | O13: =(J13-I13) -> 0 | P13: =SUM(M13:O16) -> 0
Q16: 0
A17: MERCREDI | B17: =SUM(B13+1) -> 46071 | C17: RTT | G17: 0 | H17: 0 | I17: 0 | J17: 0 | M17: =(F17-E17) -> 0 | N17: =(H17-G17) -> 0 | O17: =(J17-I17) -> 0 | P17: =SUM(M17:O20) -> 0
Q20: 0
A21: JEUDI | B21: =SUM(B17+1) -> 46072 | C21: 214365C001 217805C001 217147C001 | G21: 0.3375 | H21: 0.52083333 | I21: 0.57291667 | J21: 0.75347222 | M21: =(F21-E21) -> 0 | N21: =(H21-G21) -> 0.18333333 | O21: =(J21-I21) -> 0.18055556 | P21: =SUM(M21:O34) -> 0.36388889 | R21: 217805C001 | S21: (1h00)
S22: FLUXEL
S23: Mise en route coffret D avec variateur au R&D | V23: ok.Done
R24: 214147C001 | S24: (1h00)
S25: COIGN
S26: Envoyer ECN pour mise à jour de la logique à ALSYMEX | W26: ok.Done | X26: ECN nr: | Y26: 1027736
R27: 214365C001 | S27: (5h00)
S28: TR
S29: Maj du document ci-dessous:
T30: IOL | U30: LS_IOLC21436501 | V30: Rev6 | W30: ok.Done | X30: ECN nr: | Y30: 1027638 | Z30: MAJ DANS ARAS
T31: SDE | U31: LS_SDEC21436501 | V31: Rev9 | W31: ok.Done | X31: ECN nr: | Y31: 1027638 | Z31: MAJ DANS ARAS
T32: TBWD | U32: 24031C21436503 | W32: ok.Done | Z32: FAT accepted- TBWD OK
T33: IHD | U33: 24IHDC21436501 | V33: Rev3 | W33: ok.Done | X33: ECN nr: | Y33: 1027638 | Z33: ATTENTE RETOUR ATOS
Q34: 0.29166667
A35: Vendredi | B35: =SUM(B21+1) -> 46073 | C35: 214365C001 | G35: 0.33402778 | H35: 0.5 | I35: 0.55208333 | J35: 0.65555556 | M35: =(F35-E35) -> 0 | N35: =(H35-G35) -> 0.16597222 | O35: =(J35-I35) -> 0.10347222 | P35: =SUM(M35:O44) -> 0.26944444 | R35: 214365C001 | S35: (7h00)
S36: TR
S37: Maj du document ci-dessous:
T38: IOL | U38: LS_IOLC21436501 | V38: Rev6 | W38: ok.Done | X38: ECN nr: | Y38: 1027638 | Z38: MAJ DANS ARAS | AA38: EN ATTENTE RETOUR DOC CONTROL (Delphine)
T39: SDE | U39: LS_SDEC21436501 | V39: Rev9 | W39: ok.Done | X39: ECN nr: | Y39: 1027638 | Z39: MAJ DANS ARAS | AA39: EN ATTENTE RETOUR DOC CONTROL (Delphine)
T40: TBWD | U40: 24031C21436503 | W40: ok.Done | Z40: FAT accepted- TBWD OK
T41: IHD | U41: 24IHDC21436501 | V41: Rev3 | W41: ok.Done | X41: ECN nr: | Y41: 1027638 | Z41: ATTENTE RETOUR ATOS | AA41: EN ATTENTE RETOUR DOC CONTROL (Delphine)
T42: CEE | U42: LS_CEEC21436501 | V42: Rev4 | W42: ok.Done | X42: ECN nr: | Y42: 1027638 | Z42: ATTENTE RETOUR ATOS | AA42: EN ATTENTE RETOUR DOC CONTROL (Delphine)
T43: ILD | U43: 24ILDC21436501 | V43: Rev4 | W43: ok.Done | Z43: FAT accepted- TBWD OK
Q44: 0.29166667
A45: SAMEDI | B45: =SUM(B35+1) -> 46074 | M45: =(F45-E45)+(L45-K45) -> 0 | N45: =(H45-G45)+(J45-I45) -> 0 | O45: =(H45-G45)+(J45-I45) -> 0 | P45: =SUM(M45:O46) -> 0
A46: DIMANCHE | B46: =SUM(B45+1) -> 46075
J48: TOTAL TRAVAILLE | M48: =SUM(M9+M13+M17+M21+M35+M45+M46) -> 0 | N48: =SUM(N9+N13+N17+N21+N35+N45+N46) -> 0.34930556 | O48: =SUM(O9+O13+O17+O21+O35+O45+O46) -> 0.28402778 | P48: =SUM(P9+P13+P17+P21+P35+P45+P46) -> 0.63333333
J49: POTENTIEL SEMAINE | N49: =SUM(Q9:Q46) -> 0.58333333
J50: TOTAL SEMAINE HS | N50: =SUM(P48-N49) -> 0.05
J51: TOTAL PRECEDENT HS | N51: ='SEM7'!N85 -> 1.7881944
...

Sheet SEM9
A4: Nom: | B4: BELIN brice
A5: semaine 9 | B5: du | C5: =SUM('SEM8'!B46+1) -> 46076 | D5: au | E5: =SUM(B123) -> 46082
E6: Route | F6: aller | G6: Client ou usine | I6: Client ou usine | K6: Route retour | M6: TOTAL | Q6: potentiel jour
A7: Jour | B7: Date | C7: Nom client ou usine | E7: Heure départ | F7: Heure arrivée | G7: Heure arrivée | H7: Heure départ | I7: Heure arrivée | J7: Heure départ | K7: Heure départ | L7: Heure arrivée | M7: Heure route | N7: Heure client | O7: Heure usine | P7: Général
A9: LUNDI | B9: =SUM(C5) -> 46076 | C9: 217805C001 220594C001 221402C001 217147C001 | G9: 0.33819444 | H9: 0.52083333 | I9: 0.54166667 | J9: 0.70833333 | M9: =(F35-E35)+(L35-K35) -> 0 | N9: =(H9-G9) -> 0.18263889 | O9: =(J9-I9) -> 0.16666667 | P9: =SUM(M9:O35) -> 0.34930556 | R9: 217805C001 | S9: (3h00)
S10: FLUXEL
S11: Essai de connexion avec mon laptop | X11: ok.Done
S12: Essai de paramétrage sur variateur avec sauvegarde des données | X12: ok.Done
S13: Trouver les messages d'alarmes liés au variateurs | W13: In progress…
R14: 220594C001 | S14: (1h00)
S15: GOLAR HILLI
S16: Répondre à l'email de Rozier
S17: Maj du DBI ci-dessous:
T18: HPU | U18: 24136C22059401 | W18: ok.Done
T19: inclure l'alimentation de redondance 24136C22059401-G
R20: 221402C001 | S20: (1h00)
S21: MADINA
S22: Envoyer la codification des plans ci-dessous à Delphine: | X22: ok.Done
T23: Architecture drawing - Jetée 1 | W23: 24CSAC22140201
T24: FDS (CND) - Jetée 1 | W24: LS_CNDC22140201
T25: Modbus List - Jetée 1 | W25: LS_SDEC22140201
T26: Modbus List - Jetée 4 | W26: 24SDE05102501
T27: Modbus List - Jetée 5 | W27: 24SDE05108301
T28: Modbus List - Jetée 6 | W28: 24SDE07116701
R29: Team Meeting | S29: (1h30)
S30: Meeting avec Team JCP / HSA / HLA | V30: ok.Done
R31: 217147C001 | S31: (1h00)
S32: COIGN
S33: Maj des documents ci-dessous:
T34: CLD | U34: 24030101533022 | W34: Rev7 | X34: ok.Done | Y34: ECN nr: | Z34: 1027736 | AA34: EN ATTENTE RETOUR DOC CONTROL (Christelle)
Q35: 0.29166667
A36: MARDI | B36: =SUM(B9+1) -> 46077 | C36: 221402C001 220594C001 220267C001 214365C001 219867C001 | G36: 0.34791667 | H36: 0.48958333 | I36: 0.5625 | J36: 0.75 | M36: =(F70-E70)+(L70-K70) -> 0 | N36: =(H36-G36) -> 0.14166667 | O36: =(J36-I36) -> 0.1875 | P36: =SUM(M36:O70) -> 0.32916667 | R36: 221402C001 | S36: (1h00)
S37: MADINA
S38: Donner les dates à delphine pour les docs ci-dessouss: | W38: ok.Done
T39: Architecture drawing - Jetée 1 | W39: 24CSAC22140201 | Y39: A la PO | AA39: 46080
T40: FDS (CND) - Jetée 1 | W40: LS_CNDC22140201 | Y40: 6 week after PO | AA40: 46127
T41: Modbus List - Jetée 1 | W41: LS_SDEC22140201 | Y41: 6 week after PO | AA41: 46149
T42: Modbus List - Jetée 4 | W42: 24SDE05102501 | Y42: 6 week after PO | AA42: 46149
T43: Modbus List - Jetée 5 | W43: 24SDE05108301 | Y43: 6 week after PO | AA43: 46149
T44: Modbus List - Jetée 6 | W44: 24SDE07116701 | Y44: 6 week after PO | AA44: 46149
...

Sheet SEM10
A4: Nom: | B4: BELIN brice
A5: semaine 10 | B5: du | C5: =SUM('SEM9'!B123+1) -> 46083 | D5: au | E5: =SUM(B109) -> 46089
E6: Route | F6: aller | G6: Client ou usine | I6: Client ou usine | K6: Route retour | M6: TOTAL | Q6: potentiel jour
A7: Jour | B7: Date | C7: Nom client ou usine | E7: Heure départ | F7: Heure arrivée | G7: Heure arrivée | H7: Heure départ | I7: Heure arrivée | J7: Heure départ | K7: Heure départ | L7: Heure arrivée | M7: Heure route | N7: Heure client | O7: Heure usine | P7: Général
A9: LUNDI | B9: =SUM(C5) -> 46083 | C9: 221402C001 204291R030 | E9: 0 | F9: 0 | G9: 0.33958333 | H9: 0.52083333 | I9: 0.54166667 | J9: 0.72916667 | K9: 0 | L9: 0 | M9: =(F9-E9)+(L9-K9) -> 0 | N9: =(H9-G9) -> 0.18125 | O9: =(J9-I9) -> 0.1875 | P9: =SUM(M9:O27) -> 0.36875 | R9: 221402C001 | S9: (6h00)
S10: MADINA
S11: Création des PNs manquants ci-dessous:
T12: Fibre Optique | U12: 248990350003M | W12: ok.Done | X12: ECN nr: | Y12: 1028024 | Z12: Dispo sur ARAS | AA12: EN ATTENTE VALIDATION JCP
S13: Validation spec ELEC | U13: LS_PSEC22140201 | W13: ok.Done | X13: ECN nr: | Y13: 1028068 | Z13: Dispo sur ARAS | AA13: EN ATTENTE VALIDATION BBE
T14: Maj PN LCP | U14: 24134C22140201 | W14: ok.Done | X14: ECN nr: | Y14: 1027979 | Z14: Dispo sur ARAS | AA14: EN ATTENTE VALIDATION HLA
T15: PLC Cabinet | U15: 24134C22140202 | W15: ok.Done | X15: ECN nr: | Y15: 1027979 | Z15: Dispo sur ARAS | AA15: EN ATTENTE VALIDATION HLA
T16: LCP Assembly | U16: 24134C22140201A | W16: ok.Done | X16: ECN nr: | Y16: 1027979 | Z16: Dispo sur ARAS | AA16: EN ATTENTE VALIDATION HLA
T17: Maj EOD | U17: 24029C22140201 | W17: ok.Done | X17: ECN nr: | Y17: 1028069 | Z17: Dispo sur ARAS | AA17: EN ATTENTE VALIDATION JCP
R19: 204291R030 | S19: (1h00)
S20: ARCOS
S21: Sauvegarder la photo du départ moteur dans le répertoire du projet | X21: ok.Done
Q27: 0.29166667
A28: MARDI | B28: =SUM(B9+1) -> 46084 | C28: 216240C001 219867C001 221402C001 | E28: 0 | F28: 0 | G28: 0.36458333 | H28: 0.52083333 | I28: 0.55208333 | J28: 0.74791667 | K28: 0 | L28: 0 | M28: =(F28-E28)+(L28-K28) -> 0 | N28: =(H28-G28) -> 0.15625 | O28: =(J28-I28) -> 0.19583333 | P28: =SUM(M28:O41) -> 0.35208333 | R28: 216240C001 | S28: (5h00)
S29: MOTOR OIL
S30: Edition de la trame excel | U30: ok.Done
S31: Edition du plan ci-dessous:
T32: Archi. CS | U32: 24CSAC21624001 | W32: ok.Done
R33: 219867C001 | S33: (1h00)
S34: MARSA
S35: Remplir la feuille CRS du CEE | V35: ok.Done
R36: 221402C001 | S36: (1h00)
S37: MADINA
S38: Faire EC CL1 pour ajouter 24029 sous 24000C22140201 | W38: ok.Done
Q41: 0.29166667
A42: MERCREDI | B42: =SUM(B28+1) -> 46085 | C42: 216240C001 221402C001 220224C001 217805C001 RA172190 | E42: 0 | F42: 0 | G42: 0.31527778 | H42: 0.52083333 | I42: 0.5625 | J42: 0.7375 | K42: 0 | L42: 0 | M42: =(F42-E42)+(L42-K42) -> 0 | N42: =(H42-G42) -> 0.20555556 | O42: =(J42-I42) -> 0.175 | P42: =SUM(M42:O75) -> 0.38055556 | R42: 216240C001 | S42: (3h00)
S43: MOTOR OIL
S44: Edition du plan ci-dessous:
T45: Archi. CS | U45: 24CSAC216240011 | W45: ok.Done | X45: ECN nr: | Y45: 1028106 | Z45: Dispo sur ARAS | AA45: EN ATTENTE VALIDATION DOC CTRL (Christelle)
U46: 24CSAC216240012 | W46: ok.Done | X46: ECN nr: | Y46: 1028106 | Z46: Dispo sur ARAS
S47: Mettre les plans architecture CS sur ARAS | V47: ok.Done
R48: 221402C001 | S48: (2h00)
S49: MADINA
S50: Faire EC CL1 pour ajouter 24029 sous 24000C22140201 | W50: ok.Done | X50: ECN nr: | Y50: 1028097 | AA50: EN ATTENTE VALIDATION AVA & JCP
S51: Mah des DBIs ci-dessous:
U52: 24000C22140201 | W52: ok.Done | Z52: Dispo sur ARAS
...

Sheet SEM11
A4: Nom: | B4: BELIN brice
A5: semaine 11 | B5: du | C5: =SUM('SEM10'!B109+1) -> 46090 | D5: au | E5: =SUM(B82) -> 46096
E6: Route | F6: aller | G6: Client ou usine | I6: Client ou usine | K6: Route retour | M6: TOTAL | Q6: potentiel jour
A7: Jour | B7: Date | C7: Nom client ou usine | E7: Heure départ | F7: Heure arrivée | G7: Heure arrivée | H7: Heure départ | I7: Heure arrivée | J7: Heure départ | K7: Heure départ | L7: Heure arrivée | M7: Heure route | N7: Heure client | O7: Heure usine | P7: Général
A9: LUNDI | B9: =SUM(C5) -> 46090 | C9: 216240C001 217805C001 220224C001 | G9: 0.33680556 | H9: 0.5 | I9: 0.58333333 | J9: 0.73125 | M9: =(F9-E9)+(L9-K9) -> 0 | N9: =(H9-G9) -> 0.16319444 | O9: =(J9-I9) -> 0.14791667 | P9: =SUM(M9:O29) -> 0.31111111 | R9: 216240C001 | S9: (0h00) | U9: PAS TRAVAILLE DESSUS
S10: MOTOR OIL
S11: Edition des plans ci-dessous:
T12: Interco SOUTH | U12: 24EIDC216240012 | W12: In progress…
T13: Interco NORTH | U13: 24EIDC216240011 | W13: In progress…
R14: 217805C001 | S14: (6h00)
S15: FLUXEL
S16: Faire l'AutoTune (ID Run) | W16: In progress…
S17: Vérifiez le sens des mvts du bras:
T18: Inboard | U18: In progress…
T19: Outboard | U19: In progress…
T20: Slewing | U20: In progress…
R21: 220224C001 | S21: (1h00)
S22: ADNOC
S23: Maj de la BOM ci-dessous:
T24: HYD | U24: 24HYDC22022401IA
U25: remplacer l'item 6 - 3/8" JIC par du 5/8" JIC | X25: ok.Done | Y25: ECN nr: | Z25: 1028237 | AA25: Dispo sur ARAS | AB25: Géré par l'Inde
Q29: 0.29166667
A30: MARDI | B30: =SUM(B9+1) -> 46091 | C30: 219453C001 217805C001 | G30: 0.33402778 | H30: 0.52083333 | I30: 0.55208333 | J30: 0.70833333 | M30: =(F30-E30)+(L30-K30) -> 0 | N30: =(H30-G30) -> 0.18680556 | O30: =(J30-I30) -> 0.15625 | P30: =SUM(M30:O43) -> 0.34305556 | R30: 219453C001 | S30: (2h00)
S31: COIGN
S32: Problème de séquence sur site | U32: In progress…
S33: Répondre à l'email de Manu | U33: ok.Done
R34: 217805C001 | S34: (5h00)
S35: FLUXEL
S36: Faire l'AutoTune (ID Run) | W36: In progress…
T37: Interne | U37: ok.Done
T38: Externe | U38: Erreur : Speed cfbk configuration : 73AO | X38: In progress…
U39: Erreur : Encoder 7381
U40: Erreur : Autophasing 3385
T41: Slewing | U41: ok.Done
Q43: 0.29166667
A44: MERCREDI | B44: =SUM(B30+1) -> 46092 | C44: 217805C001 RA192454 | G44: 0.32638889 | H44: 0.5 | I44: 0.5625 | J44: 0.73680556 | M44: =(F44-E44)+(L44-K44) -> 0 | N44: =(H44-G44) -> 0.17361111 | O44: =(J44-I44) -> 0.17430556 | P44: =SUM(M44:O54) -> 0.34791667 | R44: 217805C001 | S44: (5h00)
S45: FLUXEL
S46: Se concentrer sur le variateur Slewing | V46: In progress…
T47: Paramètre TEN vide…
T48: Rentrer tous les paramètres à la main suivant feuille excel Pascal | X48: In progress…
...

Sheet SEM12
A4: Nom: | B4: BELIN brice
A5: semaine 12 | B5: du | C5: =SUM('SEM11'!B82+1) -> 46097 | D5: au | E5: =SUM(B101) -> 46103
E6: Route | F6: aller | G6: Client ou usine | I6: Client ou usine | K6: Route retour | M6: TOTAL | Q6: potentiel jour
A7: Jour | B7: Date | C7: Nom client ou usine | E7: Heure départ | F7: Heure arrivée | G7: Heure arrivée | H7: Heure départ | I7: Heure arrivée | J7: Heure départ | K7: Heure départ | L7: Heure arrivée | M7: Heure route | N7: Heure client | O7: Heure usine | P7: Général
A9: LUNDI | B9: =SUM(C5) -> 46097 | C9: Team Projects 219254C001 Point Mens. 221402C001 219867C001 217805C001 | G9: 0.36041667 | H9: 0.52083333 | I9: 0.54166667 | J9: 0.74583333 | M9: =(F9-E9)+(L9-K9) -> 0 | N9: =(H9-G9) -> 0.16041667 | O9: =(J9-I9) -> 0.20416667 | P9: =SUM(M9:O37) -> 0.36458333 | R9: Team Project | S9: (1h30)
S10: Meeting sur les docs à sortir cette semaine | V10: ok.Done
R11: 219254C001 | S11: (0h30)
S12: PADAH LNHG
S13: Meeting avec SR | V13: ok.Done
R14: Point Mensuel | S14: (0h30)
S15: Points CS | V15: PaS EU LIEU
R16: 221402C001 | S16: (1h00)
S17: MADINA
S18: Majdu document ci-dessous:
T19: LS_PSE | U19: LS_PSEC22140201 | V19: ok.Done
T20: Joindre les documents:
U21: CSA | V21: ok.Done
U22: Interco | V22: A EDITER
U23: DH | V23: PAS SUR ARAS
R24: 219867C001 | S24: (0h30)
S25: MARSA
S26: Mettre la dernière version de WinCC projet sur lien ALSYMEX | W26: ok.Done
R27: 2162540C001 | S27: (1h30)
S28: MOTOR OIL
S29: Edition du plan ci-dessous:
T30: interco SOUTH | U30: 24EIDC216240012 | V30: ok.Done | W30: EN ATTENTE VALIDATION HLA / JCP
T31: interco NORTH | U31: 24EIDC216240011 | V31: In progress…
R32: 217805C001 | S32: (2h00)
S33: FLUXEL
S34: Tet du Bp Arret Urgence | V34: ok.Done
S35: Vérification du bon fonctionnement du DataLoging | V35: ok.Done
T36: Pas de variables défini dans la sauvegarde du logiciel VFDs
Q37: 0.29166667
A38: MARDI | B38: =SUM(B9+1) -> 46098 | C38: 216240C001 219867C001 ITS 219254C001 | G38: 0.34027778 | H38: 0.52083333 | I38: 0.55208333 | J38: 0.72916667 | M38: =(F38-E38)+(L38-K38) -> 0 | N38: =(H38-G38) -> 0.18055556 | O38: =(J38-I38) -> 0.17708333 | P38: =SUM(M38:O57) -> 0.35763889 | R38: 216240C001 | S38: (3h30)
S39: MOTOR OIL
S40: Edition du plan ci-dessous:
T41: interco SOUTH | U41: 24EIDC216240012 | V41: ok.Done | W41: ECN nr: | X41: 1028433 | Y41: EN ATTENTE VALIDATION HLA / JCP
T42: interco NORTH | U42: 24EIDC216240011 | V42: ok.Done | W42: ECN nr: | X42: 1028433 | Y42: EN ATTENTE VALIDATION HLA / JCP
R43: 219867C001 | S43: (1h00)
S44: MARSA
...

Sheet SEM13
A4: Nom: | B4: BELIN brice
A5: semaine 13 | B5: du | C5: =SUM('SEM12'!B101+1) -> 46104 | D5: au | E5: =SUM(B99) -> 46110
E6: Route | F6: aller | G6: Client ou usine | I6: Client ou usine | K6: Route retour | M6: TOTAL | Q6: potentiel jour
A7: Jour | B7: Date | C7: Nom client ou usine | E7: Heure départ | F7: Heure arrivée | G7: Heure arrivée | H7: Heure départ | I7: Heure arrivée | J7: Heure départ | K7: Heure départ | L7: Heure arrivée | M7: Heure route | N7: Heure client | O7: Heure usine | P7: Général
A9: LUNDI | B9: =SUM(C5) -> 46104 | C9: 219254C001 221523C001 220594C001 219867C001 Team projects Elearning RA172190 | G9: 0.34305556 | H9: 0.52083333 | I9: 0.55208333 | J9: 0.75 | M9: =(F38-E38)+(L38-K38) -> 0 | N9: =(H9-G9) -> 0.17777778 | O9: =(J9-I9) -> 0.19791667 | P9: =SUM(M9:O38) -> 0.37569444 | R9: 219254C001 | S9: (3h00)
S10: PADAH
S11: Maj du document ci-dessous:
T12: H&E on dock | U12: 24125C21925401 | V12: ok.Done | W12: ECN nr: | X12: 1028584 | Y12: EN ATTENTE VALIDATION DOC CTRL (Christelle)
U13: voir les commentaires client avec CRS
R14: 221523C001 | S14: (1h00)
R15: RA192454 | S15: TORTUE
S16: Répondre à l'email de Mr Guillet | V16: ok.Done
S17: Mettre le plan ci-dessous sur ARAS
T18: HPU | U18: 2413619245401 | V18: ok.Done | W18: ECN nr: | X18: 1028380 | Y18: EN ATTENTE VALIDATION DOC CTRL (Delphine)
U19: ajouter PDG client
U20: ajouter numéro de projet dans cartouche plan ACE | X20: ok.Done
R21: 220594C001 | S21: (1h00)
S22: GOLAR
T23: ECD | U23: 2403015199801 | V23: ok.Done | W23: ECN nr: | X23: 1027025 | Y23: EN ATTENTE VALIDATION DOC CTRL (Christelle)
T24: LCP | U24: 2413415199801 | V24: ok.Done | W24: ECN nr: | X24: 1027025 | Y24: EN ATTENTE VALIDATION DOC CTRL (Christelle)
T25: PLC Cab. | U25: 2413415199802 | V25: ok.Done | W25: ECN nr: | X25: 1027025 | Y25: EN ATTENTE VALIDATION DOC CTRL (Christelle)
R26: 219867C001 | S26: (0h30)
S27: MARSA
S28: Conf call pour câble capteur TURCK
T29: Modifier le DBI 248991100435 | V29: ok.Done
R30: Team Project | S30: (1h00)
S31: Meeting avec la Team sur les projects | V31: ok.Done
R32: Elearning
S33: Training TEN U Signaux d'alamre de l'inginerie sociale | V33: ok.Done
R34: RA172190 | S34: (1h00)
S35: HOEGH
S36: Mettre à jour le docment ci-dessous:
T37: E&H | U37: 2412517219001 | V37: In progress…
Q38: 0.29166667
A39: MARDI | B39: =SUM(B9+1) -> 46105 | C39: RA172190 221402C001 219867C001 | G39: 0.3375 | H39: 0.52083333 | I39: 0.55208333 | J39: 0.69791667 | M39: =(F62-E62)+(L62-K62) -> 0 | N39: =(H39-G39) -> 0.18333333 | O39: =(J39-I39) -> 0.14583333 | P39: =SUM(M39:O62) -> 0.32916667 | R39: RA172190 | S39: (1h30)
S40: HOEGH
S41: Mettre à jour le document ci-dessous:
T42: E&H | U42: 2412517219001 | V42: ok.Done | W42: ECN nr: | X42: 1028609 | Y42: EN ATTENTE VALIDATION DOC CTRL (Delphine)
R43: 221402C001 | S43: (1h30)
S44: MADINA
...

Sheet 1 TRIMESTRE
A1: BELIN Brice | B1: RECAPITULATIF 1ER TRIMESTRE 2020 | E1: 43928
A4: MOIS | B4: SEMAINE | C4: CLIENT / USINE | D4: NBRE HEURES
A6: JANVIER | B6: 1 | C6: usine | D6: ='SEM1'!N54 -> 0.06875
B7: 2 | C7: usine | D7: ='SEM2'!N116 -> 0.31597222
B8: 3 | C8: usine | D8: ='SEM3'!N97 -> 0.22361111
B9: 4 | C9: usine | D9: ='SEM4'!N136 -> 0.21944444
A10: FEVRIER | B10: 5 | C10: usine | D10: ='SEM5'!N106 -> 0.3125
B11: 6 | C11: usine | D11: ='SEM6'!N113 -> 0.29166667
B12: 7 | C12: usine | D12: ='SEM7'!N83 -> 0.35625
B13: 8 | C13: usine | D13: ='SEM8'!N50 -> 0.05
A14: MARS | B14: 9 | C14: usine | D14: ='SEM9'!N127 -> 0.25694444
B15: 10 | C15: usine | D15: ='SEM10'!N113 -> 0.27083333
B16: 11 | C16: usine | D16: ='SEM11'!N86 -> 0.17152778
B17: 12 | C17: usine | D17: ='SEM12'!N105 -> 0.25972222
B18: 13 | C18: usine | D18: ='SEM13'!N103 -> 0.31041667
C26: TOTAL | D26: =SUM(D6:D24) -> 3.1076389

Sheet SEM14 
A4: Nom: | B4: BELIN brice
A5: semaine 14 | B5: du | C5: =SUM('SEM13'!B99+1) -> 46111 | D5: au | E5: =SUM(B101) -> 46117
E6: Route | F6: aller | G6: Client ou usine | I6: Client ou usine | K6: Route retour | M6: TOTAL | Q6: potentiel jour
A7: Jour | B7: Date | C7: Nom client ou usine | E7: Heure départ | F7: Heure arrivée | G7: Heure arrivée | H7: Heure départ | I7: Heure arrivée | J7: Heure départ | K7: Heure départ | L7: Heure arrivée | M7: Heure route | N7: Heure client | O7: Heure usine | P7: Général
A9: LUNDI | B9: =SUM(C5) -> 46111 | C9: 221402C001 220594C001 214523C001 Ids radio RC212649 | G9: 0.35138889 | H9: 0.52083333 | I9: 0.56944444 | J9: 0.74305556 | M9: =(F32-E32)+(L32-K32) -> 0 | N9: =(H9-G9) -> 0.16944444 | O9: =(J9-I9) -> 0.17361111 | P9: =SUM(M9:O32) -> 0.34305556 | R9: 221402C001 | S9: (2h00)
S10: MADINA
T11: Interco | U11: 24EIDC22140201 | V11: ok.Done | W11: ECN nr: | X11: 1028697 | Y11: EN ATTENTE VALIDATION DOC CTRL (Delphine)
T12: Maj de la longueur du câble Pendant : 50m
T13: CSA | U13: 24CSAC22140201 | V13: ok.Done | W13: ECN nr: | X13: 1028689 | Y13: EN ATTENTE VALIDATION DOC CTRL (Delphine)
T14: Maj suivant commentaires Delphine
R15: 220594C001 | S15: (1h00)
S16: GOLAR HILI
T17: Envoyer ECN à ACE | V17: ok.Done | W17: ECN nr: | X17: 1028710
R18: 214523C001 | S18: (0h30)
S19: EXXON TAICHANG
S20: Conf call avec Manu / Pollier / Antoine | V20: ok.Done
S21: Discussion d'une tempo de 24h pour rafraichir la position du chariot - Dmde client de la réduire à 6h ou toutes les 20 connexcions
R22: IDs radio | S22: (2h00)
S23: Maj de la BDD CAVOTEC
S24: Rajouter les Ids ci-dessous:
T25: RC172225 | U25: ID 18725 / 12213 | W25: PETRONET DAHEJ | Y25: Jetée NORTH | AA25: ok.Done
T26: RC192444 | U26: ID 19528 / Freq. 434,225 Mhz | AA26: ok.Done
T27: RC192479 | U27: ID 19770 + spare ID 18682 | W27: ESSAR/NAYARA | Y27: Radio mixte | AA27: ok.Done
T28: RA091389 | U28: ID 11845 | AA28: ok.Done
R29: RC212649 | S29: (0h30)
S30: ENAGAS
S31: Envoyez ECN pour ALSYMEX | U31: ok.Done | V31: ECN nr: | W31: 1028722
Q32: 0.29166667
A33: MARDI | B33: =SUM(B9+1) -> 46112 | C33: 219867C001 221402C001 | G33: 0.33263889 | H33: 0.52083333 | I33: 0.54166667 | J33: 0.7625 | M33: =(F46-E46)+(L46-K46) -> 0 | N33: =(H33-G33) -> 0.18819444 | O33: =(J33-I33) -> 0.22083333 | P33: =SUM(M33:O46) -> 0.40902778 | R33: 219867C001 | S33: (2h00)
S34: MARSA
S35: Regarder le calcul SIL pour ESD2 | V35: In progress…
T36: Refaire les calculs en parallèle - tableau de la trame pas fiable
S37: Envoyez ECN pour ALSYMEX (HMI) | U37: ok.Done | V37: ECN nr: | W37: 1028741
S38: Regarder le commentaires de JCp sur Bjs | V38: In progress…
R39: 221402C001 | S39: (5h00)
S40: MADINA
S41: Vérifiez le plan document ci-dessous:
T42: IOL | U42: LS_IOLC22140201 | V42: In progress…
S43: Editer le doc ci-dessous:
T44: FAT Elec | U44: LS_EFPC22140201 | V44: In progress…
...

Sheet SEM15
A4: Nom: | B4: BELIN brice
A5: semaine 15 | B5: du | C5: =SUM('SEM14 '!B101+1) -> 46118 | D5: au | E5: =SUM(B71) -> 46124
E6: Route | F6: aller | G6: Client ou usine | I6: Client ou usine | K6: Route retour | M6: TOTAL | Q6: potentiel jour
A7: Jour | B7: Date | C7: Nom client ou usine | E7: Heure départ | F7: Heure arrivée | G7: Heure arrivée | H7: Heure départ | I7: Heure arrivée | J7: Heure départ | K7: Heure départ | L7: Heure arrivée | M7: Heure route | N7: Heure client | O7: Heure usine | P7: Général
A9: LUNDI | B9: =SUM(C5) -> 46118 | C9: FERIE | G9: 0 | H9: 0 | I9: 0 | J9: 0 | M9: =(F12-E12)+(L12-K12) -> 0 | N9: =(H9-G9) -> 0 | O9: =(J9-I9) -> 0 | P9: =SUM(M9:O12) -> 0
Q12: 0
A13: MARDI | B13: =SUM(B9+1) -> 46119 | C13: 219867C001 221402C001 220594C001 | G13: 0.34166667 | H13: 0.52083333 | I13: 0.5625 | J13: 0.73125 | M13: =(F13-E13)+(L13-K13) -> 0 | N13: =(H13-G13) -> 0.17916667 | O13: =(J13-I13) -> 0.16875 | P13: =SUM(M13:O31) -> 0.34791667 | R13: 219867C001 | S13: (3h00)
S14: MARSA
S15: Editer les DBIs pour les étiquettes des BJs pour tous les bras:
T16: bras nr1 | U16: 2489915C21986701 | V16: ok.Done
T17: bras nr2 | U17: 2489915C21986702 | V17: ok.Done
T18: bras nr3 | U18: 2489915C21986703 | V18: ok.Done
S19: Ajouter les DBIs ans les DBIs méca ci-dessous:
T20: bras nr1 | U20: 24013C21986701 | V20: In progress…
T21: bras nr2 | U21: 24013C21986702 | V21: In progress…
T22: bras nr3 | U22: 24013C21986703 | V22: In progress…
R23: 221402C001 | S23: (3h00)
S24: MADINA
S25: Vérifiez le plan document ci-dessous:
T26: IOL | U26: LS_IOLC22140201 | V26: ok.Done
R27: 220594C001 | S27: (1h00)
S28: GOLAR HILLI
S29: Maj du plan ci-dessous:
T30: SVA | U30: 2413315199801 | V30: ok.Done | W30: ECN nr: | X30: 1028710 | Y30: EN ATTENTE VALIDATION DOC CTRL (Christelle)
Q31: 0.29166667
A32: MERCREDI | B32: =SUM(B13+1) -> 46120 | C32: 219867C001 221402C001 220594C001 | G32: 0.30763889 | H32: 0.52083333 | I32: 0.5625 | J32: 0.7375 | M32: =(F32-E32)+(L32-K32) -> 0 | N32: =(H32-G32) -> 0.21319444 | O32: =(J32-I32) -> 0.175 | P32: =SUM(M32:O48) -> 0.38819444 | R32: 219867C001 | S32: (2h00)
S33: MARSA
S34: Editer les DBIs pour les étiquettes des BJs pour tous les bras:
T35: bras nr1 | U35: 2489915C21986701 | V35: ok.Done | W35: ECN nr: | X35: 1028859 | Y35: EN ATTENTE VALIDATION BE CS (JR)
T36: bras nr2 | U36: 2489915C21986702 | V36: ok.Done
T37: bras nr3 | U37: 2489915C21986703 | V37: ok.Done
S38: Ajouter les DBIs ans les DBIs méca ci-dessous:
T39: bras nr1 | U39: 24013C21986701 | V39: ok.Done | W39: ECN nr: | X39: 1028857 | Y39: EN ATTENTE VALIDATION BE CS (FPR)
T40: bras nr2 | U40: 24013C21986702 | V40: ok.Done
T41: bras nr3 | U41: 24013C21986703 | V41: ok.Done
R42: 221402C001 | S42: (5h00)
S43: MADINA
S44: Maj du document ci-dessous:
T45: Interco | U45: 24EIDC22140201 | V45: In progress…
S46: Edition du document ci-dessous:
...

Sheet SEM16
A4: Nom: | B4: BELIN brice
A5: semaine 16 | B5: du | C5: =SUM('SEM15'!B71+1) -> 46125 | D5: au | E5: =SUM(B25) -> 46131
E6: Route | F6: aller | G6: Client ou usine | I6: Client ou usine | K6: Route retour | M6: TOTAL | Q6: potentiel jour
A7: Jour | B7: Date | C7: Nom client ou usine | E7: Heure départ | F7: Heure arrivée | G7: Heure arrivée | H7: Heure départ | I7: Heure arrivée | J7: Heure départ | K7: Heure départ | L7: Heure arrivée | M7: Heure route | N7: Heure client | O7: Heure usine | P7: Général
A9: LUNDI | B9: =SUM(C5) -> 46125 | C9: RTT | G9: 0 | H9: 0 | I9: 0 | J9: 0 | M9: =(F9-E9)+(L9-K9) -> 0 | N9: =(H9-G9) -> 0 | O9: =(J9-I9) -> 0 | P9: =SUM(M9:O11) -> 0
Q11: 0
A12: MARDI | B12: =SUM(B9+1) -> 46126 | C12: RTT | G12: 0 | H12: 0 | I12: 0 | J12: 0 | M12: =(F14-E14)+(L14-K14) -> 0 | N12: =(H12-G12) -> 0 | O12: =(J12-I12) -> 0 | P12: =SUM(M12:O14) -> 0
Q14: 0
A15: MERCREDI | B15: =SUM(B12+1) -> 46127 | C15: RTT | G15: 0 | H15: 0 | I15: 0 | J15: 0 | M15: =(F15-E15)+(L15-K15) -> 0 | N15: =(H15-G15) -> 0 | O15: =(J15-I15) -> 0 | P15: =SUM(M15:O17) -> 0
Q17: 0
A18: JEUDI | B18: =SUM(B15+1) -> 46128 | C18: RTT | G18: 0 | H18: 0 | I18: 0 | J18: 0 | M18: =(F20-E20)+(L20-K20) -> 0 | N18: =(H18-G18) -> 0 | O18: =(J18-I18) -> 0 | P18: =SUM(M18:O20) -> 0
Q20: 0
A21: VENDREDI | B21: =SUM(B18+1) -> 46129 | C21: RTT | G21: 0 | H21: 0 | I21: 0 | J21: 0 | M21: =(F23-E23)+(L23-K23) -> 0 | N21: =(H21-G21) -> 0 | O21: =(J21-I21) -> 0 | P21: =SUM(M21:O23) -> 0
Q23: 0
A24: SAMEDI | B24: =SUM(B21+1) -> 46130 | M24: =(F24-E24)+(L24-K24) -> 0 | N24: =(G24-F24)+(M24-L24) -> 0 | O24: =(H25-G25)+(J25-I25) -> 0 | P24: =(I25-H25)+(K25-J25) -> 0
A25: DIMANCHE | B25: =SUM(B24+1) -> 46131
J27: TOTAL TRAVAILLE | M27: =SUM(M9+M12+M15+M18+M21+M24+M25) -> 0 | N27: =SUM(N9+N12+N15+N18+N21+N24+N25) -> 0 | O27: =SUM(O9+O12+O15+O18+O21+O24+O25) -> 0 | P27: =SUM(P9+P12+P15+P18+P21+P24+P25) -> 0
J28: POTENTIEL SEMAINE | N28: =SUM(Q9:Q25) -> 0
J29: TOTAL SEMAINE HS | N29: =SUM(P27-N28) -> 0
J30: TOTAL PRECEDENT HS | N30: ='SEM15'!N77 -> 0.35972222
J31: NOUVEAU TOTAL HS | N31: =N29+N30 -> 0.35972222

Sheet SEM17
A4: Nom: | B4: BELIN brice
A5: semaine 17 | B5: du | C5: =SUM('SEM16'!B25+1) -> 46132 | D5: au | E5: =SUM(B99) -> 46138
E6: Route | F6: aller | G6: Client ou usine | I6: Client ou usine | K6: Route retour | M6: TOTAL | Q6: potentiel jour
A7: Jour | B7: Date | C7: Nom client ou usine | E7: Heure départ | F7: Heure arrivée | G7: Heure arrivée | H7: Heure départ | I7: Heure arrivée | J7: Heure départ | K7: Heure départ | L7: Heure arrivée | M7: Heure route | N7: Heure client | O7: Heure usine | P7: Général
A9: LUNDI | B9: =SUM(C5) -> 46132 | C9: Team Meeting 219867C001 214936C001 219254C001 | G9: 0.34375 | H9: 0.52083333 | I9: 0.54166667 | J9: 0.70694444 | M9: =(F27-E27)+(L27-K27) -> 0 | N9: =(H9-G9) -> 0.17708333 | O9: =(J9-I9) -> 0.16527778 | P9: =SUM(M9:O27) -> 0.34236111 | R9: Team Meeting | S9: (1h30)
S10: Réunion Team Meeting | U10: ok.Done
R11: 219867C001 | S11: (3h30)
S12: MARSA
S13: Maj du plan ci-dessous:
T14: CSA | U14: 24CSAC21986701 | V14: ok.Done | W14: ECN nr: | X14: 1029043 | Y14: EN ATTENTE VALIDATION DOC CTRL (Christelle)
S15: Edition du plan:
T16: CSA_02 | U16: 24CSAC21986702 | V16: In progress…
U17: voir projet 220881 AKSO NL 2
R18: 214936C001 | S18: (1h00)
S19: WISON
S20: Envoyez un emailk à ALSYMEX pour avoir des captures écran de l'HMI | X20: ok.Done
T21: les mêmes que sur le document LS_HMIC21493601
R22: 219254C001 | S22: (1h00)
S23: PADAH
S24: Maj du plan ci-dessous:
T25: HCD | U25: 24HCDC21925401 | V25: In progress… | W25: ECN nr: | X25: 1029046
U26: remplir la CRS…
Q27: 0.29166667
A28: MARDI | B28: =SUM(B9+1) -> 46133 | C28: 219254C001 221402C001 220198C001 219867C001 | G28: 0.33958333 | H28: 0.48611111 | I28: 0.54166667 | J28: 0.75347222 | M28: =(F49-E49)+(L49-K49) -> 0 | N28: =(H28-G28) -> 0.14652778 | O28: =(J28-I28) -> 0.21180556 | P28: =SUM(M28:O49) -> 0.35833333 | R28: 219254C001 | S28: (5h00)
S29: PADAH
S30: Maj du plan ci-dessous:
T31: HCD | U31: 24HCDC21925401 | V31: ok.Done | W31: ECN nr: | X31: 1029046 | Y31: EN ATTENTE VALIDATION DOC CTRL (Christelle)
U32: remplir la CRS…
T33: E&H on Dock | U33: 24125C2192401 | V33: ok.Done | W33: ECN nr: | X33: 1029067 | Y33: EN ATTENTE VALIDATION DOC CTRL (Christelle)
U34: remplir la CRS…
T35: CND | U35: LS_CNDC21925401 | V35: ok.Done
R36: 221402C001 | S36: (1h00)
S37: MADINA
S38: Mettre à jour le DBI PLC Cabinet
T39: DBI | U39: 24134C22140202 | V39: ok.Done | W39: ECN nr: | X39: 1029084 | Y39: EN ATTENTE VALIDATION BE CS (FPR)
R40: 220198C001 | S40: (0h30)
S41: SHELL PRELUDE
T42: HMI | U42: LCP | V42: Voir avec JCP pour sauvegarde - Rien sur notre Serveur PLC
U43: Control Room
R44: 219867C001 | S44: (1h00)
...

Sheet SEM18
A4: Nom: | B4: BELIN brice
A5: semaine 18 | B5: du | C5: =SUM('SEM17'!B99+1) -> 46139 | D5: au | E5: =SUM(B62) -> 46145
E6: Route | F6: aller | G6: Client ou usine | I6: Client ou usine | K6: Route retour | M6: TOTAL | Q6: potentiel jour
A7: Jour | B7: Date | C7: Nom client ou usine | E7: Heure départ | F7: Heure arrivée | G7: Heure arrivée | H7: Heure départ | I7: Heure arrivée | J7: Heure départ | K7: Heure départ | L7: Heure arrivée | M7: Heure route | N7: Heure client | O7: Heure usine | P7: Général
A9: LUNDI | B9: =SUM(C5) -> 46139 | C9: 219867C001 Supervision Param VFDs | G9: 0.35138889 | H9: 0.52083333 | I9: 0.54166667 | J9: 0.70486111 | M9: =(F32-E32)+(L32-K32) -> 0 | N9: =(H9-G9) -> 0.16944444 | O9: =(J9-I9) -> 0.16319444 | P9: =SUM(M9:O32) -> 0.33263889 | R9: 219867C001 | S9: (5h30)
S10: MARSA
S12: Envoyer le plan ci-dessous au Doc Control:
S13: Cyber | T13: 24CSAC219867012 | U13: ok.Done | V13: ECN nr: | W13: 1029158 | X13: EN ATTENTE signature JCP & HLA | AA13: EN ATTENTE validation DOC CTRL
S15: Codifier les détcteurs ci-dessous:
S16: Détecteur inductif cylindrique M18 / noyable / câble moulé Lg 2m / détection 10mm au mini / avec plage de température étendue | AC16: réf actuelle: | AD16: NI10-P18-Y1/S100 | AG16: équivalence: | AH16: BI5-P18-Y1/S100 | AK16: ok.Done | AL16: ECN nr: | AM16: 1029161 | AN16: EN ATTENTE validation HLA
S17: Qtés: | T17: 4 (pour 1 bras) | AD17: ne convient pas | AH17: 248991100439
AH18: Géom - 248991100439 | AL18: ECN nr: | AM18: 1029160 | AN18: EN ATTENTE validation BBE
S19: Détecteur inductif cylindrique M30 / noyable / câble moulé Lg 15m / détection 10mm au mini | AC19: réf actuelle: | AD19: NI15-P30-YX | AG19: équivalence: | AH19: BI10-P30-Y1X/12M ? | AK19: ok.Done | AL19: ECN nr: | AM19: 1029161 | AN19: EN ATTENTE validation HLA
S20: Qtés: | T20: 6 (pour 1 bras) | AD20: ne convient pas | AH20: 248991100438
S21: Inversion de l'interlock dans le SVA | W21: ok.Done | X21: Fait par l"équipe YT | AH21: Géom - 248991100438 | AL21: ECN nr: | AM21: 1029160 | AN21: EN ATTENTE validation BBE
S22: Inversion des mouvements pour le slewing sur le CPMS+ | W22: ok.Done | X22: EN ATTENTE correction de AF
S24: IDS | T24: LS_IDSC21986701
T25: Maj du document suite retour commentaires client, | X25: In progress…
R26: Supervision | S26: (1h30)
S27: Supervision Fronted Live Review
S28: Meeting BE CS avec présentation du Camille | W28: ok.Done
R29: VFDs | S29: (1h00)
S30: Review Paramètres VFDs
S31: Meeting avec Anthony sur les paramètres VFDs a considéré par le PLC pour le projet AKKER | Y31: ok.Done
Q32: 0.29166667
A33: MARDI | B33: =SUM(B9+1) -> 46140 | C33: 219867C001 | G33: 0.34375 | H33: 0.52083333 | I33: 0.54166667 | J33: 0.75 | M33: =(F42-E42)+(L42-K42) -> 0 | N33: =(H33-G33) -> 0.17708333 | O33: =(J33-I33) -> 0.20833333 | P33: =SUM(M33:O42) -> 0.38541667 | R33: 219867C001 | S33: (7h00)
S34: MARSA
S35: IDS | T35: LS_IDSC21986701
T36: Maj du document suite retour commentaires client | X36: In progress…
S37: Meeting Charly / FPR pour proximiy switche ST80 & alarmes | W37: ok.Done
S38: Maj du DBI ci-dessous:
T39: 248991100438 | W39: ok.Done | X39: ECN nr: | Y39: 1029205 | Z39: EN ATTENTE VALIDATION BE CS (HLA)
T40: modifier M30x1,5
Q42: 0.29166667
A43: MERCREDI | B43: =SUM(B33+1) -> 46141 | C43: 219867C001 | G43: 0.31388889 | H43: 0.52083333 | I43: 0.5625 | J43: 0.73402778 | M43: =(F49-E49)+(L49-K49) -> 0 | N43: =(H43-G43) -> 0.20694444 | O43: =(J43-I43) -> 0.17152778 | P43: =SUM(M43:O49) -> 0.37847222 | R43: 219867C001 | S43: (7h00)
S44: MARSA
S45: IDS | T45: LS_IDSC21986701 | W45: ok.Done | X45: ECN nr: | Y45: 1029238 | Z45: EN ATTENTE SIGNATURES FPR & HLA | AD45: EN ATTENTE validation DOC CTRL
T46: Maj du document suite retour commentaires client
S47: Maj du plan ci-dessous:
S48: E&H on Arm | T48: 24EOAC21986701 | W48: In progress…
...

Sheet SEM19
A4: Nom: | B4: BELIN brice
A5: semaine 19 | B5: du | C5: =SUM('SEM18'!B62+1) -> 46146 | D5: au | E5: =SUM(B78) -> 46152
E6: Route | F6: aller | G6: Client ou usine | I6: Client ou usine | K6: Route retour | M6: TOTAL | Q6: potentiel jour
A7: Jour | B7: Date | C7: Nom client ou usine | E7: Heure départ | F7: Heure arrivée | G7: Heure arrivée | H7: Heure départ | I7: Heure arrivée | J7: Heure départ | K7: Heure départ | L7: Heure arrivée | M7: Heure route | N7: Heure client | O7: Heure usine | P7: Général
A9: LUNDI | B9: =SUM(C5) -> 46146 | C9: 219867C001 219254C001 221402C001 | G9: 0.34097222 | H9: 0.5 | I9: 0.5625 | J9: 0.74236111 | M9: =(F39-E39)+(L39-K39) -> 0 | N9: =(H9-G9) -> 0.15902778 | O9: =(J9-I9) -> 0.17986111 | P9: =SUM(M9:O39) -> 0.33888889 | R9: 219254C001 | S9: (0h30)
S10: PADAH
S11: Meeting avec SR sur état de docs | V11: ok.Done
R12: 219867C001 | S12: (4h00)
S13: MARSA
S14: Voir la NC4366 sur les BJs & les plugs M32 & M25 manquant | W14: ok.Done
T15: BJ CPMS | U15: 24JBDC21986701 | X15: plan conforme à la spec ls_JBS | AA15: Ou sont les 2 plugs M32 & M25 manquants??
U16: spec LS_JBSC21986701
T17: BJ BR 3/3 | U17: 24JBDC21986704 | X17: plan conforme à la spec ls_JBS | AA17: Ou sont les 2 plugs M32 & M25 manquants??
U18: spec LS_JBSC21986704
S19: Editer les DBIs ci-dessous:
T20: Plug M32 | U20: 248990600306 | W20: In progress… | X20: Envoyé email à Charly pour les référencdes et les qtés
T21: Ecrou M32 | U21: 248990700208
T23: Plug M25 | U23: 248990600234 | W23: In progress… | X23: Envoyé email à Charly pour les référencdes et les qtés
T24: Ecrou M25 | U24: 248990700207
S25: Mettre le lan ci-dessous sur ARAS:
T26: IDS | U26: LS_IDSC21986701 | W26: ok.Done | X26: ECN nr: | Y26: 1029238 | Z26: EN ATTENTE validation DOC CTRL (Christelle)
R28: 221402C001 | S28: (2h30)
S29: MADINA
S30: Maj du plan ci-dessous:
T31: CSA | U31: 24CSAC22140201 | W31: In progress… | X31: ECN nr: | Y31: 1029300
T32: mettre à jour suite diffusion de l'architecture par ALSYMEX
T33: CND | U33: LS_CNDC22140201 | W33: ok.Done | X33: ECN nr: | Y33: 1029296 | Z33: EN ATTENTE validation DOC CTRL (Delphine)
T34: finir edition du CND
T35: Reprendre la page de garde client MADINA
Q39: 0.29166667
A40: MARDI | B40: =SUM(B9+1) -> 46147 | C40: 221402C001 219867C001 | G40: 0.325 | H40: 0.52083333 | I40: 0.55208333 | J40: 0.74375 | M40: =(F50-E50)+(L50-K50) -> 0 | N40: =(H40-G40) -> 0.19583333 | O40: =(J40-I40) -> 0.19166667 | P40: =SUM(M40:O50) -> 0.3875 | R40: 221402C001 | S40: (3h00)
S41: MADINA
S42: Maj du plan ci-dessous:
T43: CSA | U43: 24CSAC22140201 | W43: ok.Done | X43: ECN nr: | Y43: 1029300
T44: mettre à jour suite diffusion de l'architecture par ALSYMEX
R45: 219867C001 | S45: (4h00)
S46: MARSA
S47: Vérification du document ci-dessous:
T48: HMI | U48: LS_HMIC21986701 | W48: ok.Done | X48: ECN nr: | Y48: 1029296 | Z48: EN ATTENTE signature HLA & JCP
Q50: 0.29166667
...

Sheet SEM20
A4: Nom: | B4: BELIN brice
A5: semaine 20 | B5: du | C5: =SUM('SEM19'!B78+1) -> 46153 | D5: au | E5: =SUM(B69) -> 46159
E6: Route | F6: aller | G6: Client ou usine | I6: Client ou usine | K6: Route retour | M6: TOTAL | Q6: potentiel jour
A7: Jour | B7: Date | C7: Nom client ou usine | E7: Heure départ | F7: Heure arrivée | G7: Heure arrivée | H7: Heure départ | I7: Heure arrivée | J7: Heure départ | K7: Heure départ | L7: Heure arrivée | M7: Heure route | N7: Heure client | O7: Heure usine | P7: Général
A9: LUNDI | B9: =SUM(C5) -> 46153 | C9: 219254C001 221402C001 Meeting BE CS | E9: 0 | F9: 0 | G9: 0.34652778 | H9: 0.52083333 | I9: 0.54166667 | J9: 0.72152778 | M9: =(F9-E9)+(L9-K9) -> 0 | N9: =(H9-G9) -> 0.17430556 | O9: =(J9-I9) -> 0.17986111 | P9: =SUM(M9:O28) -> 0.35416667 | R9: 219254C001 | S9: (5h00)
S10: PADAH
S11: Maj du plan ci-dessous:
T12: PID | U12: 24PIDC21925401 | W12: ok.Done | X12: ECN nr: | Y12: 1029416 | Z12: EN ATTENTE VALIDATION DOC CTRL (Christelle)
T13: Répondre à la CRS du client
T14: SDE | W14: ok.Done | X14: EN ATTENTE RETOUR PM
T15: Envoyer les commentaires à ALSYMEX
R16: 221402C001 | S16: (2h00)
S17: MADINA
S18: Meeting avec ALSYMEX sur les plans CSA & EID | W18: In progress…
S19: Mettre le plan ci-dessous sur ARAS:
T20: IOL | U20: LS_IOLC22140201 | W20: ok.Done | X20: ECN nr: | Y20: 1029390 | Z20: EN ATTENTE MEETING ALSYMEX
T21: EID | U21: 24EIDC22140201 | W21: ok.Done | X21: ECN nr: | Y21: 1029343 | Z21: EN ATTENTE MEETING ALSYMEX
T22: CSA | U22: 24CSAC22140201 | W22: ok.Done | X22: ECN nr: | Y22: 1029300 | Z22: EN ATTENTE MEETING ALSYMEX
S23: Maj du plan ci-dessous:
T24: LS_EFP | U24: LS_EFPC22140201 | W24: In progress… | X24: ECN nr: | Y24: 1029386
T25: mettre à jour suite commentaires client
R26: Point projets | S26: (1h30)
S27: Meeting Trinome BE CS sur les projets | W27: ok.Done
Q28: 0.29166667
A29: MARDI | B29: =SUM(B9+1) -> 46154 | C29: 221402C001 219254C001 | E29: 0 | F29: 0 | G29: 0.34444444 | H29: 0.52083333 | I29: 0.5625 | J29: 0.74722222 | N29: =(H29-G29) -> 0.17638889 | O29: =(J29-I29) -> 0.18472222 | P29: =SUM(M29:O43) -> 0.36111111 | R29: 221402C001 | S29: (3h00)
S30: MADINA
S31: Véifier le document ci-dessous:
T32: IOL | U32: LS_IOLC22140201 | W32: ok.Done | X32: ECN nr: | Y32: 1029390 | Z32: EN ATTENTE VALIDATION DOC CTRL (Delphine)
T33: EID | U33: 24EIDC22140201 | W33: In progress… | X33: ECN nr: | Y33: 1029343
T34: remplir la CRS
T35: CSA | U35: 24CSAC22140201 | W35: ok.Done | X35: ECN nr: | Y35: 1029300 | Z35: EN ATTENTE VALIDATION DOC CTRL (Delphine)
S36: Maj du plan ci-dessous:
T37: LS_EFP | U37: LS_EFPC22140201 | W37: In progress… | X37: ECN nr: | Y37: 1029386
R38: 219254C001 | S38: (4h00)
S39: PADAH
S40: Maj du plan ci-dessous:
T41: PID | U41: 24PIDC21925401 | W41: ok.Done | X41: ECN nr: | Y41: 1029416 | Z41: EN ATTENTE VALIDATION DOC CTRL (Christelle)
T42: Répondre à la CRS du client
Q43: 0.29166667
A44: MERCREDI | B44: =SUM(B29+1) -> 46155 | C44: 221402C001 216240C001 | E44: 0 | F44: 0 | G44: 0.30555556 | H44: 0.52083333 | I44: 0.5625 | J44: 0.71666667 | M44: =(F44-E44)+(L44-K44) -> 0 | N44: =(H44-G44) -> 0.21527778 | O44: =(J44-I44) -> 0.15416667 | P44: =SUM(M44:O52) -> 0.36944444 | R44: 221402C001 | S44: (5h00)
...

Sheet SEM21
A4: Nom: | B4: BELIN brice
