Workbook

Sheet SEM1
A4: Nom: | B4: BELIN brice
A5: semaine 1 | B5: du | C5: 45656 | D5: au | E5: =SUM(B56) -> 45662
E6: Route | F6: aller | G6: Client ou usine | I6: Client ou usine | K6: Route retour | M6: TOTAL | Q6: potentiel jour
A7: Jour | B7: Date | C7: Nom client ou usine | E7: Heure départ | F7: Heure arrivée | G7: Heure arrivée | H7: Heure départ | I7: Heure arrivée | J7: Heure départ | K7: Heure départ | L7: Heure arrivée | M7: Heure route | N7: Heure client | O7: Heure usine | P7: Général
A9: LUNDI | B9: =SUM(C5) -> 45656 | C9: VACANCES | G9: 0 | H9: 0 | I9: 0 | J9: 0 | M9: =(F11-E11)+(L11-K11) -> 0 | N9: =(H9-G9) -> 0 | O9: =(J9-I9) -> 0 | P9: =SUM(M9:O11) -> 0
Q11: 0
A12: MARDI | B12: =SUM(B9+1) -> 45657 | C12: VACANCES | G12: 0 | H12: 0 | I12: 0 | J12: 0 | M12: =(F14-E14)+(L14-K14) -> 0 | N12: =(H12-G12) -> 0 | O12: =(J12-I12) -> 0 | P12: =SUM(M12:O14) -> 0
Q14: 0
A15: MERCREDI | B15: =SUM(B12+1) -> 45658 | C15: VACANCES | G15: 0 | H15: 0 | I15: 0 | J15: 0 | M15: =(F17-E17)+(L17-K17) -> 0 | N15: =(H15-G15) -> 0 | O15: =(J15-I15) -> 0 | P15: =SUM(M15:O17) -> 0
Q17: 0
A18: JEUDI | B18: =SUM(B15+1) -> 45659 | C18: Conductix 218099C001 216956C001 217052C001 217785C001 | G18: 0.3375 | H18: 0.52083333 | I18: 0.5625 | J18: 0.70972222 | M18: =(F40-E40)+(L40-K40) -> 0 | N18: =(H18-G18) -> 0.18333333 | O18: =(J18-I18) -> 0.14722222 | P18: =SUM(M18:O40) -> 0.33055556 | R18: Conductix | S18: (1h00)
S19: Equivalent face T
S20: Chercher des images plus netes pour la radio equivalente Face T | X20: ok.Done
R21: 218099C001 | S21: (1h00)
S22: Motor Oil
S23: Ranger les plans envoyés par Alsymex ci-dessous:
T24: 2413410152101 | U24: LCP | V24: Rev 8 | W24: ok.Done
T25: 2403010152101 | U25: ECD | V25: Rev 7 | W25: ok.Done
S26: Déjà présent dans ARAS | U26: ok.Done
R27: 216956C001 | S27: (2h30)
S28: LYONDELL
S29: Mettre a jour les tags dans interco | U29: ok.Done
S30: Mettre à jour les tags dans le plan TBWD | V30: In progress…
T31: Demander les sources AutoCAD complètes à Alsymex | X31: ok.Done
S32: Envoyer le plan ECD à ACE | U32: ok.Done
R33: 217052C001 | S33: (0h30)
S34: Adriatic LNG
S35: FAT procedure codification
S36: Codifier ce document sur ARAS | U36: ok.Done
R37: 217785C001 | S37: (1h00)
S38: PEROU LNG
S39: Mettre les plans LCP & ECD sur ARAS | V39: ok.Done
Q40: 0.29166667
A41: VENDREDI | B41: =SUM(B18+1) -> 45660 | C41: 216956C001 215732C001 214365C001 | G41: 0.33125 | H41: 0.52430556 | I41: 0.55208333 | J41: 0.68958333 | M41: =(F54-E54)+(L54-K54) -> 0 | N41: =(H41-G41) -> 0.19305556 | O41: =(J41-I41) -> 0.1375 | P41: =SUM(M41:O54) -> 0.33055556 | R41: 216956C001 | S41: (4h00)
S42: LYONDELL
S43: Mettre à jour les tags dans le plan TBWD | V43: ok.Done
S44: Faire email à Loic pour demande de retour des plans interco & TBWD suite à la maj des tags | Y44: ok.Done
R45: 215732C001 | S45: (1h00)
S46: Costa Azul
S47: Discussion avec JCP sur la validation du changement d'huile | W47: ok.Done
...

Sheet SEM2
A4: Nom: | B4: BELIN brice
A5: semaine 2 | B5: du | C5: =SUM('SEM1'!B56+1) -> 45663 | D5: au | E5: =SUM(B103) -> 45669
E6: Route | F6: aller | G6: Client ou usine | I6: Client ou usine | K6: Route retour | M6: TOTAL | Q6: potentiel jour
A7: Jour | B7: Date | C7: Nom client ou usine | E7: Heure départ | F7: Heure arrivée | G7: Heure arrivée | H7: Heure départ | I7: Heure arrivée | J7: Heure départ | K7: Heure départ | L7: Heure arrivée | M7: Heure route | N7: Heure client | O7: Heure usine | P7: Général
A9: LUNDI | B9: =SUM(C5) -> 45663 | C9: 214365C001 218020C001 RA172190 219204C001 | G9: 0.35972222 | H9: 0.52083333 | I9: 0.57291667 | J9: 0.74652778 | M9: =(F28-E28)+(L28-K28) -> 0 | N9: =(H9-G9) -> 0.16111111 | O9: =(J9-I9) -> 0.17361111 | P9: =SUM(M9:O28) -> 0.33472222 | R9: 214365C001 | S9: (1h30)
S10: TR
S11: Mettre à jour les plans ci-dessous:
S12: 24ECDC21436502 | U12: ECD - Motor Starter | W12: en Rev 0 & AFC | Y12: In progress…
S13: LS_IOLC21436501 | U13: IOL including soft (Cavotec) | X13: voir la rev actuelle | Z13: In progress…
R14: 218020C001 | S14: (1h00)
S15: TCC
S16: Maj du plan 24125C21802001 | V16: ok.Done | W16: Attente VOR de la part d'Alsparlan
S17: Editer le tableau de paramétrage CPMS | V17: Rescheduled to Thursday 09/01
R18: RA172190 | S18: (0h30)
S19: HOEGH
S20: Rajouter la note dans le plan 2412517219001 | W20: ok.Done
S21: Mettre le plan sous ARAS | U21: ok.Done
R22: 5S | S22: (1h00)
S23: Remettre son bureau en etat fonctionnel | V23: ok.Done
R24: 219204C001 | S24: (2h30)
S25: ARAMCO OVERSEA
S26: KOM | T26: ok.Done
S27: Edition trame excel | U27: ok.Done
Q28: 0.29166667
A29: MARDI | B29: =SUM(B9+1) -> 45664 | C29: RA172190 Alsymex docs 216956C001 218020C001 | G29: 0.33263889 | H29: 0.52083333 | I29: 0.55208333 | J29: 0.71041667 | M29: =(F45-E45)+(L45-K45) -> 0 | N29: =(H29-G29) -> 0.18819444 | O29: =(J29-I29) -> 0.15833333 | P29: =SUM(M29:O45) -> 0.34652778 | R29: RA172190 | S29: (1h00)
S30: HOEGH
S31: Repasser en Rev 1 | U31: ok.Done
R32: Alsymex docs | S32: (0h30)
S33: Meeting for all documentations on projets with Alsymex | W33: ok.Done
R34: 216956C001 | S34: (0h30)
S35: LYONDELLBASE
S36: Maj du plan 24133C21695601 en Rev 1 | V36: In progress…
R37: 214936C001 | S37: (1h00)
S38: Wison
S39: Maj du plan Data Sheets for Hydraulic Components:
T40: 33HCC21493601 | V40: ok.Done
S41: Validation de la modification d'ACE sur le "ARM SELECTION MANUAL OVERRIDE" | Y41: Suivi par Francois…
R42: 218020C001 | S42: (0h30)
S43: TCC
S44: Faire email à ATOS avec demande de date pour l'envoie des documents | X44: ok.Done
...

Sheet SEM3
A4: Nom: | B4: BELIN brice
A5: semaine 3 | B5: du | C5: =SUM('SEM2'!B103+1) -> 45670 | D5: au | E5: =SUM(B102) -> 45676
E6: Route | F6: aller | G6: Client ou usine | I6: Client ou usine | K6: Route retour | M6: TOTAL | Q6: potentiel jour
A7: Jour | B7: Date | C7: Nom client ou usine | E7: Heure départ | F7: Heure arrivée | G7: Heure arrivée | H7: Heure départ | I7: Heure arrivée | J7: Heure départ | K7: Heure départ | L7: Heure arrivée | M7: Heure route | N7: Heure client | O7: Heure usine | P7: Général
A9: LUNDI | B9: =SUM(C5) -> 45670 | C9: 218020C001 214365C001 Performance Aide Réception 219030C001 216696C001 | G9: 0.35833333 | H9: 0.52083333 | I9: 0.56944444 | J9: 0.70902778 | M9: =(F9-E9)+(L9-K9) -> 0 | N9: =(H9-G9) -> 0.1625 | O9: =(J9-I9) -> 0.13958333 | P9: =SUM(M9:O33) -> 0.30208333 | R9: 218020C001 | S9: (2h30)
S10: TCC
S11: Envoyez à ACTEMIUM la dernière version du prog CPMS | X11: ok.Done
S12: Répondre à l'email ATOS pour les commenatires sur plan HCD | X12: ok.Done
R13: 214365C001 | S13: (1h00)
S14: TR
S15: Reprendre la liste des docs à mettre à jour | W15: In progress…
T16: Motor Data Sheet | V16: LS_MDSC21436501 | X16: In progress…
R18: Performance Appraisal | T18: (1h30)
T19: Entretien indiv. Avec François | W19: In progress… | X19: Move to Friday 17/01/25
R20: Réception TEN | S20: (1h00)
S21: Aide pour Adnane | U21: In progress…
T22: Email envoyé à ACE pour confirmation de référence | X22: ok.Done
T23: En attente de retour de la part d'ACE | W23: ok.Done
S24: Aide pour Eric | U24: ok.Done
R25: 219030C001 | S25: (2h00)
S26: TAL OIL
S27: Répondre à l'email d'ALSYMEX | V27: ok.Done
T28: Numéro ECN, plans | V28: ok.Done
S29: Faire email à Robin pour dmde de plans Berths2,3 et 4 au client | X29: In progress…
R30: 216696C001 | S30: (1h00)
S31: QCLNG
S32: Mettre à jour le DBI nr: | U32: 2413810149601 | V32: In progress…
Q33: 0.29166667
A34: MARDI | B34: =SUM(B9+1) -> 45671 | C34: 216696C001 214365C001 Quality 219123C001 | G34: 0.32986111 | H34: 0.52083333 | I34: 0.54166667 | J34: 0.72708333 | M34: =(F34-E34)+(L34-K34) -> 0 | N34: =(H34-G34) -> 0.19097222 | O34: =(J34-I34) -> 0.18541667 | P34: =SUM(M34:O50) -> 0.37638889 | R34: 216696C001
S35: QCLNG
S36: Mettre à jour le DBI nr: | U36: 2413810149601 | V36: In progress…
R37: 214365C001 | S37: (1h00)
S38: TR
S39: Reprendre la liste des docs à mettre à jour | W39: In progress…
T40: Motor Data Sheet | V40: LS_MDSC21436501 | X40: In progress…
R41: Quality | S41: (1h00)
S42: Adnane
S43: Call avec lui pour le problème de références
R44: 219123C001 | S44: (1h00)
S45: TEN AUSTRALIA
...

Sheet SEM4
A4: Nom: | B4: BELIN brice
A5: semaine 4 | B5: du | C5: =SUM('SEM3'!B102+1) -> 45677 | D5: au | E5: =SUM(B109) -> 45683
E6: Route | F6: aller | G6: Client ou usine | I6: Client ou usine | K6: Route retour | M6: TOTAL | Q6: potentiel jour
A7: Jour | B7: Date | C7: Nom client ou usine | E7: Heure départ | F7: Heure arrivée | G7: Heure arrivée | H7: Heure départ | I7: Heure arrivée | J7: Heure départ | K7: Heure départ | L7: Heure arrivée | M7: Heure route | N7: Heure client | O7: Heure usine | P7: Général
A9: LUNDI | B9: =SUM(C5) -> 45677 | C9: 219204C001 214936C001 214365C001 218020C001 | G9: 0.36458333 | H9: 0.52083333 | I9: 0.55208333 | J9: 0.68541667 | M9: =(F9-E9)+(L9-K9) -> 0 | N9: =(H9-G9) -> 0.15625 | O9: =(J9-I9) -> 0.13333333 | P9: =SUM(M9:O25) -> 0.28958333 | R9: 219204C001 | S9: (1h00)
S10: ARAMCO
S11: Faire le lancement LF | U11: ok.Done
R12: 214936C001 | S12: (1h00)
S13: Wison | U13: ok.Done
S14: Meeting punch list
S15: Appelez Alsymex (Berger) pour problème de zoom sur hmi | X15: ok.Done | Z15: En attente call de C.Berger
R16: 214365C001 | S16: (2h00)
S17: TR
S18: Reprendre la liste des docs à mettre à jour | W18: In progress…
T19: HART transmitter Database | V19: LS_HTDC21436501 | X19: ok.Done | Z19: Sent to Doc Control | AB19: Refused byDoc Control
T20: Instrument Cable List | V20: LS_ICLC21436501 | X20: ok.Done
T21: Software Datasheet Ex. | V21: LS_SDEC21436501 | X21: In progress…
R22: 218020C001 | S22: (1h30)
S23: TCC
S24: Meeting avec CORAIL pour intégration CPMS avec TIA PORTAL V19 | X24: ok.Done
Q25: 0.29166667
A26: MARDI | B26: =SUM(B9+1) -> 45678 | C26: 214365C001 ITS Docs projets 219124C001 RA081269 216696C001 | G26: 0.32916667 | H26: 0.52083333 | I26: 0.55208333 | J26: 0.70902778 | M26: =(F26-E26)+(L26-K26) -> 0 | N26: =(H26-G26) -> 0.19166667 | O26: =(J26-I26) -> 0.15694444 | P26: =SUM(M26:O44) -> 0.34861111 | R26: 214365C001 | S26: (4h00)
S27: TR
S28: Reprendre la liste des docs à mettre à jour | W28: In progress…
T29: HART transmitter Database | V29: LS_HTDC21436501 | X29: ok.Done | Z29: Sent to Doc Control
T30: Terminal Box Wiring Diagram | V30: 24031C21436503 | X30: ok.Done | Z30: En attente retour fichier CRS Volkan
R31: ITS | S31: (0h30)
S32: Remplir la feuille d'heure du mis de Janvier jusqu'au 23/01 | W32: In progress…
R33: Docs projets | S33: (0h30)
S34: Meeting avec Wael sur la documentation en cours des projets | W34: ok.Done
R35: 219124C001 | S35: (0h30)
S36: Lire email de Luc sur les coupleurs | V36: ok.Done
R37: RA081269 | S37: (1h00)
S38: Golar Freeze FSRU
S39: Support line pour Alain Dica (Insrum. STE) | V39: In progress…
R40: 216696C001 | S40: (1h00)
S41: QCLNG
T42: Control Logic Diagram | V42: 2403010149602 | X42: In progress… | Z42: En attente info client…
T43: Hydraulic Control Panel | V43: 2113410149601 | X43: In progress… | Z43: En attente info client…
Q44: 0.29166667
...

Sheet SEM5
A4: Nom: | B4: BELIN brice
A5: semaine 5 | B5: du | C5: =SUM('SEM4'!B109+1) -> 45684 | D5: au | E5: =SUM(B117) -> 45690
E6: Route | F6: aller | G6: Client ou usine | I6: Client ou usine | K6: Route retour | M6: TOTAL | Q6: potentiel jour
A7: Jour | B7: Date | C7: Nom client ou usine | E7: Heure départ | F7: Heure arrivée | G7: Heure arrivée | H7: Heure départ | I7: Heure arrivée | J7: Heure départ | K7: Heure départ | L7: Heure arrivée | M7: Heure route | N7: Heure client | O7: Heure usine | P7: Général
A9: LUNDI | B9: =SUM(C5) -> 45684 | C9: CONDUCTIX 214365C001 218020C001 219124C001 | G9: 0.32777778 | H9: 0.52430556 | I9: 0.55208333 | J9: 0.73402778 | M9: =(F21-E21)+(L21-K21) -> 0 | N9: =(H9-G9) -> 0.19652778 | O9: =(J9-I9) -> 0.18194444 | P9: =SUM(M9:O21) -> 0.37847222 | R9: Conductix | S9: (2h00)
S10: Prépararer les PNs dans ARAS | V10: In progress…
R11: 214365C001 | S11: (1h30)
S12: TR
S13: En attente d'ATOS pour les docs ci-dessous: | V13: ok.Done
T14: SVA dwg | V14: 24133C21802001 | X14: ok.Done
T15: HPU dwg | V15: 24136C21802001 | X15: ok.Done
S16: En attente validation ARAS | V16: In progress…
S17: Maj plan ERS Accu 16" | V17: 24141C214365012 | X17: ok.Done
R18: 219124C001 | S18: (2h30)
S19: ARAMCO
S20: Préparation du lancement Partiel | V20: In progress…
Q21: 0.29166667
A22: MARDI | B22: =SUM(B9+1) -> 45685 | C22: 219124C001 219453C001 Pt Docs 217052C001 214365C001 | G22: 0.33194444 | H22: 0.52083333 | I22: 0.55208333 | J22: 0.70902778 | M22: =(F42-E42)+(L42-K42) -> 0 | N22: =(H22-G22) -> 0.18888889 | O22: =(J22-I22) -> 0.15694444 | P22: =SUM(M22:O42) -> 0.34583333 | R22: 219124C001 | S22: (2h00)
S23: ARAMCO
S24: Edition des plans ci-dessous: | V24: In progress…
T25: Hydraulic Circuit Diagram | V25: 24HCDC21912401 | X25: Berth 17 | Y25: In progress…
V26: 24HCDC21912402 | X26: Berth 18 | Y26: In progress…
S27: Valider les numéros de plans avec JCP | V27: ok.Done
R28: 219453C001 | S28: (1h00)
S29: COIGN
S30: Meeting avec Wael
R31: Point Docs | S31: (0h30)
S32: Point avec Wael/JCP/François | V32: ok.Done
R33: 217052C001 | S33: (0h30)
S34: ADRIATIC
S35: Envoyez les différents plans à Philippe | V35: ok.Done
R36: 214365C001 | S36: [2h00)
S37: TR
S38: Envoyez email à ATOS pour les docs ci-dessous:
T39: Instrument Data Sheet | V39: LS_IDSC21436501 | X39: In progress…
T40: Motor Data Sheet | V40: LS_MDSC21436501 | X40: ok.Done
T41: HPU Noise Data Sheet | V41: LS_NDSC21436501 | X41: In progress…
Q42: 0.29166667
A43: MERCREDI | B43: =SUM(B22+1) -> 45686 | C43: 219124C001 CONDUCTIX 219453C001 216696C001 Qualité | G43: 0.33125 | H43: 0.5 | I43: 0.58333333 | J43: 0.75069444 | M43: =(F63-E63)+(L63-K63) -> 0 | N43: =(H43-G43) -> 0.16875 | O43: =(J43-I43) -> 0.16736111 | P43: =SUM(M43:O63) -> 0.33611111 | R43: 219124C001 | S43: (5h00)
S44: ARAMCO
...

Sheet SEM6
A4: Nom: | B4: BELIN brice
A5: semaine 6 | B5: du | C5: =SUM('SEM5'!B117+1) -> 45691 | D5: au | E5: =SUM(B111) -> 45697
E6: Route | F6: aller | G6: Client ou usine | I6: Client ou usine | K6: Route retour | M6: TOTAL | Q6: potentiel jour
A7: Jour | B7: Date | C7: Nom client ou usine | E7: Heure départ | F7: Heure arrivée | G7: Heure arrivée | H7: Heure départ | I7: Heure arrivée | J7: Heure départ | K7: Heure départ | L7: Heure arrivée | M7: Heure route | N7: Heure client | O7: Heure usine | P7: Général
A9: LUNDI | B9: =SUM(C5) -> 45691 | C9: AM Absent 217785C001 219059C001 Quality | G9: 0 | H9: 0 | I9: 0.51319444 | J9: 0.7125 | M9: =(F9-E9)+(L9-K9) -> 0 | N9: =(H9-G9) -> 0 | O9: =(J9-I9) -> 0.19930556 | P9: =SUM(M9:O30) -> 0.19930556 | R9: 217785C001 | S9: (1h00)
S10: PEROU LNG
S11: Problème avec étiquette radio CAVOTEC | V11: In progress…
S12: Envoi d'email à Alsymex | U12: ok.Done
R13: 219124C001 | S13: (0h30)
S14: ARAMCO
S15: Refaire le lien de la feuille de lancement partiel | W15: ok.Done
R16: 219059C001 | S16: (0h30)
S17: EG LNG
S18: Maj des DBIs ci-dessous: | U18: ok.Done
T19: Set of MC3000…repairing | V19: 248993504342310 | X19: ok.Done
T20: Set of MC3000…repairing | V20: 248993504342311 | X20: ok.Done
R21: 219123C001 | S21: (1h00)
S22: TEN AUSTRALIA
S23: Maj DBIs | T23: ok.Done
T24: BJ | U24: nok | V24: 33145C21912302 | X24: Attente VOR
T25: Cables BJ | U25: nok | X25: Attente VOR
T26: Moteur hydrauliq. MRD4500L | V26: 338982000016 | X26: ok.Done
R27: Quality | S27: (1h00)
S28: Pb transmetteur - Eric Chardonnier & ACE | V28: In progress…
S29: Renvoyer les informations à Eric & Adnane | V29: ok.Done
Q30: 0.16666667
A31: MARDI | B31: =SUM(B9+1) -> 45692 | C31: Quality 218020C001 Doc ARAS Docs Proj. Buyer | G31: 0.32847222 | H31: 0.52083333 | I31: 0.55208333 | J31: 0.72638889 | M31: =(F31-E31)+(L31-K31) -> 0 | N31: =(H31-G31) -> 0.19236111 | O31: =(J31-I31) -> 0.17430556 | P31: =SUM(M31:O46) -> 0.36666667 | R31: Quality | S31: (1h00)
S32: Pb transmetteur - Eric Chardonnier & ACE | V32: ok.Done
S33: Répondre email d'ACE | V33: ok.Done
R34: 218020C001 | S34: (2h00)
S35: Valider les plans d'ATOS | U35: In progress…
T36: JB | V36: ok.Done | X36: En attente retour JCP
T37: Motor Starter | V37: ok.Done | X37: En attente retour JCP
T38: SVA | V38: In progress…
R39: DOC ARAS | S39: (1h00)
S40: Meeting information sur la documentation sur ARAS | W40: ok.Done
R41: Docs Proj | S41: (0h30)
S42: Meeting Fraçois / Wael sur les docs par projet | W42: ok.Done
R43: Buyer | S43: (0h30)
S44: Maj DBI ci-dessous
...

Sheet SEM7
A4: Nom: | B4: BELIN brice
A5: semaine 7 | B5: du | C5: =SUM('SEM6'!B111+1) -> 45698 | D5: au | E5: =SUM(B98) -> 45704
E6: Route | F6: aller | G6: Client ou usine | I6: Client ou usine | K6: Route retour | M6: TOTAL | Q6: potentiel jour
A7: Jour | B7: Date | C7: Nom client ou usine | E7: Heure départ | F7: Heure arrivée | G7: Heure arrivée | H7: Heure départ | I7: Heure arrivée | J7: Heure départ | K7: Heure départ | L7: Heure arrivée | M7: Heure route | N7: Heure client | O7: Heure usine | P7: Général
A9: LUNDI | B9: =SUM(C5) -> 45698 | C9: Pont 2025 RA192437 217785C001 218020C001 CONDUCTIX | G9: 0.36041667 | H9: 0.52083333 | I9: 0.56597222 | J9: 0.73333333 | M9: =(F9-E9) -> 0 | N9: =(H9-G9) -> 0.16041667 | O9: =(J9-I9) -> 0.16736111 | P9: =SUM(M9:O28) -> 0.32777778 | R9: Pont 2025 | S9: (0h30)
S10: Meeting avec JCP / Wael | U10: ok.Done
R11: CONDUCTIX | S11: (0h30)
S12: Conf call avec Mr Aymes concernant la nouvelle face avant equivalente Face T de CAVOTEC | Z12: ok.Done
S13: Diffuser à Anthony, François et Jean-Claude pour avoir leurs avis | X13: In progress…
R14: RA192437 | S14: (2h30)
S15: PIPECHINA
S16: Problème avec le capteur de sélection "Arm Selected" | W16: In progress…
T17: P&F | U17: P/N: | V17: 70133044 | X17: Réf: | Y17: NCB4-12GM40-N0-V1 | AA17: Lien: | AB17: NCB4-12GM40-N0-V1
T18: Editer trame de problème | V18: ok.Done
T19: Répondre à l'email de Robin | V19: ok.Done
R20: 217785C001 | S20: (1h00)
S21: PEROU
S22: Allez chercher les etiquettes CAVOTEC à la réception | W22: ok.Done
S23: Demande à Nathalie qui contacter pour ouvrir les caisses | X23: In progress… | Y23: En attente retour d'info Marion
R24: 218020C001 | S24: (2h00)
S25: TCC
S26: Répondre à ATOS pour la largeur du SVA | W26: ok.Done
S27: Répondre à ATOS concernant la SIC et la ligne d'asséchage N2 | X27: In progress…
Q28: 0.29166667
A29: MARDI | B29: =SUM(B9+1) -> 45699 | C29: RA192437 219124C001 | G29: 0.33125 | H29: 0.51388889 | I29: 0 | J29: 0 | M29: =(F36-E36)+(L36-K36) -> 0 | N29: =(H29-G29) -> 0.18263889 | O29: =(J29-I29) -> 0 | P29: =SUM(M29:O36) -> 0.18263889 | R29: RA192437 | S29: (2h30)
S30: PIPECHINA
S31: Répondre aux emails de Robin | V31: ok.Done
S32: Chercher la doc technique sur les barrières SI MTL 5517 | W32: ok.Done
R33: 219124C001 | S33: (1h30)
S34: ARAMCO
S35: Edition du plan Motor Starter | V35: 24MDSC21912401 | X35: ok.Done
Q36: 0.16666667
A37: MERCREDI | B37: =SUM(B29+1) -> 45700 | C37: 218020C001 RA212635 RA202549 214365C001 RA172190 219124C001 | G37: 0.30208333 | H37: 0.52777778 | I37: 0.5625 | J37: 0.73333333 | M37: =(L37-K37) -> 0 | N37: =(H37-G37) -> 0.22569444 | O37: =(J37-I37) -> 0.17083333 | P37: =SUM(M37:O62) -> 0.39652778 | R37: 218020C001 | S37: (3h00)
S38: TCC
S39: Répondre à ATOS concernant la SIC et la ligne d'asséchage N2 | X39: In progress…
S40: Appelez Alsparslan pour parler de l'email de Airoldi | W40: ok.Done
S41: Mettre à jour la BOM E&H sur plan 24125 | V41: In progress… | W41: En attente retour de FP pour l'ECN CL1 sur le DBI 24028C21802001
S42: Répondre à l'email de Mr Airoldi sur l'encombrement du SVA | X42: ok.Done
S43: Préparer la trame client à envoyer à ATOS pour le HPU Noise | X43: ok.Done
R44: RA212635 | S44: (0h30)
...

Sheet SEM8
A4: Nom: | B4: BELIN brice
A5: semaine 8 | B5: du | C5: =SUM('SEM7'!B98+1) -> 45705 | D5: au | E5: =SUM(B146) -> 45711
E6: Route | F6: aller | G6: Client ou usine | I6: Client ou usine | K6: Route retour | M6: TOTAL | Q6: potentiel jour
A7: Jour | B7: Date | C7: Nom client ou usine | E7: Heure départ | F7: Heure arrivée | G7: Heure arrivée | H7: Heure départ | I7: Heure arrivée | J7: Heure départ | K7: Heure départ | L7: Heure arrivée | M7: Heure route | N7: Heure client | O7: Heure usine | P7: Général
A9: LUNDI | B9: =SUM(C5) -> 45705 | C9: 219254C001 219124C001 216482C001 | G9: 0.35763889 | H9: 0.52083333 | I9: 0.56944444 | J9: 0.7375 | M9: =(F9-E9) -> 0 | N9: =(H9-G9) -> 0.16319444 | O9: =(J9-I9) -> 0.16805556 | P9: =SUM(M9:O46) -> 0.33125 | R9: 219254C001 | S9: (2h00)
S10: PADAH LNG
S11: Création des PNs manquant | U11: ok.Done
S12: Edition du plan EOA | U12: 24EOAC21925401 | W12: In progress…
R13: 219124C001 | S13: (2h00)
S14: ARAMCO | T14: ok.Done
S15: Maj à jour des DBIs - Ajout de la radio et des ses accessoires:
T16: LCP - BERTH 17 | V16: 24134C219124011 | X16: ok.Done | Y16: Déjà inclut dans la BOM
T17: LCP - BERTH 18 | V17: 24134C219124012 | X17: ok.Done | Y17: Déjà inclut dans la BOM
T18: Faire le LF | U18: ok.Done
S19: Remplir la SDCL d'ACE | U19: ok.Done | V19: Envoyé à Laurent Roz,
R20: RC202549 | S20: (0h30)
S21: Golden Pass
S22: Meeting Orla/Sharad sur la mise à jour des docs qui sort du scope originel | Y22: ok.Done
R23: Points docs | S23: (1h00)
S24: Meeting points docs pour les projets ci-dessous: | W24: ok.Done
T25: 219124C001 | U25: ARAMCO | V25: Faire le LF | Z25: ok.Done
T26: 219254C001 | U26: PADAH | V26: Quels plans en priorité? | Z26: In progress…
X27: Spec | Y27: (1j) | AA27: Editeur: BB
X28: hydrauliq | Y28: ATTENTION AU SVA | AA28: Editeur: JCP
X29: interco | AA29: Editeur: WKT
X30: CS Archi | AA30: Editeur: WKT | AB30: A VALIDER
X31: Motor Starter | AA31: Editeur: BB | AB31: Scope client
X32: EOA | AA32: Editeur: BB | AB32: in progress…
T33: 218020C001 | U33: TCC | V33: Validation de l'HPU & ERS pour lancer la fabrication chez ATOS | AA33: ok.Done
V34: HPU | W34: ok
V35: ERS | W35: ok | X35: En attente retour d'ATOS en Rev 1
T36: 219370C001 | U36: GOLDEN PASS
V37: Voir avec françois pour que l'Inde la documentation
R38: 214365C001 | S38: (1h00)
S39: TR
S40: Envoyez email à ATOS pour les docs ci-dessous: | W40: ok.Done
T41: Instrument Data Sheet | V41: LS_IDSC21436501 | X41: In progress… | Y41: En attente retour d'ATOS
T42: HPU Noise Data Sheet | V42: LS_NDSC21436501 | X42: In progress… | Y42: En attente retour d'ATOS
R43: 216482C001 | S43: (1h00)
S44: ARAMCO
...

Sheet SEM9
A4: Nom: | B4: BELIN brice
A5: semaine 9 | B5: du | C5: =SUM('SEM8'!B146+1) -> 45712 | D5: au | E5: =SUM(B100) -> 45718
E6: Route | F6: aller | G6: Client ou usine | I6: Client ou usine | K6: Route retour | M6: TOTAL | Q6: potentiel jour
A7: Jour | B7: Date | C7: Nom client ou usine | E7: Heure départ | F7: Heure arrivée | G7: Heure arrivée | H7: Heure départ | I7: Heure arrivée | J7: Heure départ | K7: Heure départ | L7: Heure arrivée | M7: Heure route | N7: Heure client | O7: Heure usine | P7: Général
A9: LUNDI | B9: =SUM(C5) -> 45712 | C9: 214365C001 219254C001 RA192454 | G9: 0.34236111 | H9: 0.52083333 | I9: 0.56944444 | J9: 0.73680556 | M9: =(F25-E25)+(L25-K25) -> 0 | N9: =(H9-G9) -> 0.17847222 | O9: =(J9-I9) -> 0.16736111 | P9: =SUM(M9:O25) -> 0.34583333 | R9: 214365C001 | S9: (1h00)
S10: TR
S11: Ajouter les signature sur le document ci-dessous:
T12: CND | U12: LS_CNDC21436501 | W12: ECN nr: | X12: 1020213 | Y12: ok.Done
R13: 219254C001 | S13: (4h00)
S14: PADAH LNG
S15: Maj des plans ci-dessous:
T16: EOA | U16: 24EOAC21925401 | W16: In progress… | X16: Prévoir les PMAFLEX pour tous les câbles
T17: Spec Elec & Hydrau | W17: In progress… | X17: Généré les PDF excel Elec & hydrau | AA17: En attente validation JCP
R18: RA192454 | S18: (0h30)
S19: TORTUE
S20: Vérifier si condition PERC ARMED dans la logic Rev7 pour le "FLOW OUTLET" | Y20: ok.Done
T21: Mettre à jour la logique avec le nouvelle condition + baisser les seuils des flow inlet à 175-150l/min
R22: 219453C001 | S22: (1h00)
S23: COIGN
S24: Faire le check avec Wael sur les DBIs + la feuille de lancement | X24: ok.Done
Q25: 0.29166667
A26: MARDI | B26: =SUM(B9+1) -> 45713 | C26: 219254C001 218020C001 216956C001 216696C001 RA172190 | G26: 0.34583333 | H26: 0.52430556 | I26: 0.5625 | J26: 0.71180556 | M26: =(F54-E54)+(L54-K54) -> 0 | N26: =(H26-G26) -> 0.17847222 | O26: =(J26-I26) -> 0.14930556 | P26: =SUM(M26:O54) -> 0.32777778 | R26: 219254C001 | S26: (5h00)
S27: PADAH LNG
S28: Maj des plans ci-dessous:
T29: EOA | U29: 24EOAC21925401 | W29: ok.Done | X29: Prévoir les PMAFLEX pour tous les câbles
T30: Spec Elec & Hydrau | W30: ok.Done | X30: Envoyer les excel à Laurent Rozier
T31: UCL | U31: LS_UCLC21925401 | W31: ok.Done | X31: A faire valider par Jean Claude
R32: 218020C001
S33: TCC
S34: Opérating envelopp mise à jour
S35: Vérifiez les paramètres CPMS+ | V35: In progress…
R36: 216956C001 | S36: (0h30)
S37: LYONDELL
S38: Maj du plan:
T39: LCP | U39: 2413412174001 | W39: ok.Done
R40: 216696C001 | S40: (0h30)
S41: QCLNG
S42: Répondre à l'émail d'Adrien (ALSYMEX) | V42: ok.Done
S43: Demander à JCP la confirmation de ne pas envoyer les infos ST80 LEFT & RIGHT dans la SDE
S44: Pourquoi avoir séparé les 2 Evs LEFT & RIGHT (dans BJ non safety & BJ Safety)
...

Sheet SEM10
A4: Nom: | B4: BELIN brice
A5: semaine 10 | B5: du | C5: =SUM('SEM9'!B100+1) -> 45719 | D5: au | E5: =SUM(B90) -> 45725
E6: Route | F6: aller | G6: Client ou usine | I6: Client ou usine | K6: Route retour | M6: TOTAL | Q6: potentiel jour
A7: Jour | B7: Date | C7: Nom client ou usine | E7: Heure départ | F7: Heure arrivée | G7: Heure arrivée | H7: Heure départ | I7: Heure arrivée | J7: Heure départ | K7: Heure départ | L7: Heure arrivée | M7: Heure route | N7: Heure client | O7: Heure usine | P7: Général
A9: LUNDI | B9: =SUM(C5) -> 45719 | C9: CONDUCTIX 219124C001 216956C001 219254C001 | E9: 0 | F9: 0 | G9: 0.35833333 | H9: 0.52083333 | I9: 0.5625 | J9: 0.71875 | K9: 0 | L9: 0 | M9: =(F9-E9)+(L9-K9) -> 0 | N9: =(H9-G9) -> 0.1625 | O9: =(J9-I9) -> 0.15625 | P9: =SUM(M9:O25) -> 0.31875 | R9: Conductix | S9: (1h00)
S10: Chercher la doc des "STATUS" pour Anthony | W10: ok.Done
S11: Envoie d'un email à CONDUCTIX (Mr Aymes) | W11: ok.Done | X11: En attente du retour
R12: 219124C001 | S12: (1h30)
S13: ARAMCO
S14: Envoyé la lste docuùmentaire à ALSYMEX | W14: ok.Done
S15: Envoyé le CDC à Laurent Rozier | V15: ok.Done
R16: 216956C001 | S16: (0h30)
S17: LYONDELLBASE
S18: CD de fin d'affaire envoyé par ACE | V18: ok.Done
S19: Le mettre dans le dossier projet | V19: ok.Done
R20: 219254C001 | S20: (4h00)
S21: PADAH LNG
S22: Maj des DBIs ci-dessous:
T23: PC CPMS | W23: In progress…
T24: Deskop prog | W24: In progress…
Q25: 0.29166667
A26: MARDI | B26: =SUM(B9+1) -> 45720 | C26: RC182278 214365C001 RA192437 Software Spare Parts | E26: 0 | F26: 0 | G26: 0.33472222 | H26: 0.52083333 | I26: 0.55208333 | J26: 0.70833333 | K26: 0 | L26: 0 | M26: =(F26-E26)+(L26-K26) -> 0 | N26: =(H26-G26) -> 0.18611111 | O26: =(J26-I26) -> 0.15625 | P26: =SUM(M26:O45) -> 0.34236111 | R26: RC182278
S27: BRUNEI
S28: Valider le plan24HMI par JCP avant envoi au DC | W28: In progress…
R29: 214365C001 | S29: (2h00)
S30: TR
S31: Maj des plans ci-dessous:
T32: Motor Data Sheet | V32: LS_MDSC21436501 | X32: ok.Done
T33: Software Data Exchange | V33: LS_SDEC21436501 | X33: In progress…
R34: RA192437 | S34: (1h30)
S35: PIPECHINA
S36: Meeting avec JCP | U36: ok.Done
S37: Editer nouvelle procédure | U37: ok.Done
S38: Faire valider par JCP | U38: In progress…
R39: Software | S39: (1h00)
S40: Téléchargement de TIA PORTAL V20 | V40: ok.Done
S41: Vérifiez si clé TIA PORTAL V20 dans EKB Free Siemens License | X41: In progress…
R42: Spare Parts | S42: (0h30)
S43: Codification de la référence CAVOTEC ci-dessous:
T44: Chargeur de batterie | V44: réf: | W44: M5-1080-3624 | X44: 24899CAV0084 | Z44: ECN nr: | AA44: 1020431 | AB44: In progress… | AC44: En attente validation JCP
...

Sheet SEM11
A4: Nom: | B4: BELIN brice
A5: semaine 11 | B5: du | C5: =SUM('SEM10'!B90+1) -> 45726 | D5: au | E5: =SUM(B117) -> 45732
E6: Route | F6: aller | G6: Client ou usine | I6: Client ou usine | K6: Route retour | M6: TOTAL | Q6: potentiel jour
A7: Jour | B7: Date | C7: Nom client ou usine | E7: Heure départ | F7: Heure arrivée | G7: Heure arrivée | H7: Heure départ | I7: Heure arrivée | J7: Heure départ | K7: Heure départ | L7: Heure arrivée | M7: Heure route | N7: Heure client | O7: Heure usine | P7: Général
A9: LUNDI | B9: =SUM(C5) -> 45726 | C9: 218020C001 219254C001 CONDUCTIX 216696C001 RA212678 Services | G9: 0.36041667 | H9: 0.52083333 | I9: 0.5625 | J9: 0.72708333 | M9: =(F9-E9)+(L9-K9) -> 0 | N9: =(H9-G9) -> 0.16041667 | O9: =(J9-I9) -> 0.16458333 | P9: =SUM(M9:O29) -> 0.325 | R9: 21820C001 | S9: (0h30)
S10: Conf call avec JCP pour répondre à l'email d'ATOS | W10: ok.Done
R11: 219254C001 | S11: (3h30)
S12: PADAH LNG
T13: Maj des docs ci-dessous:
U14: EOA | V14: 24EOAC21925401 | X14: In progress… | Y14: A mettre à jour
U15: CND | V15: LS_CNDC21925401 | X15: ok.Done | Y15: En attente de validation de JCP
U16: EID | V16: 24EIDC21925401 | X16: ok.Done | Y16: Maj des désignations câbles pge 05/05
R17: CONDUCTIX | S17: (1h30)
S18: Meeting avec Conductix / JCP | V18: ok.Done
S19: Validation des PNs materiels pour ARAS | W19: In progress… | X19: En attente de validation de JCP
S20: Faire la modification de la Face avant T | W20: In progress…
R21: 216696C001 | S21: (0h30)
S22: QCLNG
S23: Répondre à Adrien (ASLYMEX) | V23: ok.Done
R24: RA212678 | S24: (1h00)
S25: ITHK
S26: Envoyer email à Siemens pour problème de certificat sur PC CPMS | X26: ok.Done
R27: Support to Services | T27: (1h00)
S28: Faire la procédure pour connaitre la version de Windows & l'état de la licence | Y28: ok.Done
Q29: 0.29166667
A30: MARDI | B30: =SUM(B9+1) -> 45727 | C30: CONDUCTIX RA212635 219254C001 | G30: 0.32430556 | H30: 0.52083333 | I30: 0.55208333 | J30: 0.74375 | M30: =(F30-E30)+(L30-K30) -> 0 | N30: =(H30-G30) -> 0.19652778 | O30: =(J30-I30) -> 0.19166667 | P30: =SUM(M30:O50) -> 0.38819444 | R30: CONDUCTIX | S30: (4h00)
S31: Validation des PNs materiels pour ARAS | W31: In progress… | X31: En attente de validation de JCP
S32: Faire la modification de la Face avant T | W32: In progress…
R33: RA212635 | S33: (1h00)
S34: MRY
S35: Faire email à Anthony / Camille | V35: ok.Done
R36: 219254C001 | S36: (1h00)
S37: PADAH LNG
S38: Mettre les plans ci-dessous sur ARAS
S39: HCD | T39: 24HCDC21925401 | V39: Rev 0 | W39: ok.Done | X39: ECN nr | Y39: 1020584
S40: EID | T40: 24EIDC21925401 | V40: Rev 1 | W40: ok.Done
S41: CND | T41: LS_CNDC21925401 | V41: Rev 0 | W41: ok.Done
S42: IOL | T42: LS_IOLC21925401 | V42: Rev 0 | W42: ok.Done
R43: 219124C001 | S43: (1h00)
S44: ARAMCO
...

Sheet SEM12
A4: Nom: | B4: BELIN brice
A5: semaine 12 | B5: du | C5: =SUM('SEM11'!B117+1) -> 45733 | D5: au | E5: =SUM(B114) -> 45739
E6: Route | F6: aller | G6: Client ou usine | I6: Client ou usine | K6: Route retour | M6: TOTAL | Q6: potentiel jour
A7: Jour | B7: Date | C7: Nom client ou usine | E7: Heure départ | F7: Heure arrivée | G7: Heure arrivée | H7: Heure départ | I7: Heure arrivée | J7: Heure départ | K7: Heure départ | L7: Heure arrivée | M7: Heure route | N7: Heure client | O7: Heure usine | P7: Général
A9: LUNDI | B9: =SUM(C5) -> 45733 | C9: CAVOTEC 219254C001 CONDUCTIX IQ | G9: 0.36041667 | H9: 0.52083333 | I9: 0.56944444 | J9: 0.72916667 | M9: =(F9-E9)+(L9-K9) -> 0 | N9: =(H9-G9) -> 0.16041667 | O9: =(J9-I9) -> 0.15972222 | P9: =SUM(M9:O24) -> 0.32013889 | R9: CAVOTEC | S9: (1h30)
S10: Ajouter les nouveaux Ids dans la BDD | V10: ok.Done
R11: 219254C001 | S11: (5h00)
S12: PADAH LNH
T13: Codifier les PE PMAFLEX ci-dessous:
U14: PE NW10 / M16 P1-L | V14: ref: | W14: NENZ0203S/P2-L | X14: ok.Done | Y14: DBI nr: | Z14: 248991600715
U15: PE NW10 / M16 P2-L | V15: ref: | W15: NENZ0203S/P1-L | X15: ok.Done | Y15: DBI nr: | Z15: 248991600667
S16: Mettre à jour le plan EOA | U16: ok.Done
S17: Mettre à jour le plan PID | U17: ok.Done
R19: CONDUCTIX | S19: (0h30)
S20: Demander à remettre le commutateur du coupleur sur la droite avec un emplacement vide | Y20: ok.Done
R21: IQ | S21: (0h30)
S22: Règles de formalisme
T23: 1ère réunion pour parler des besoins | V23: ok.Done
Q24: 0.29166667
A25: MARDI | B25: =SUM(B9+1) -> 45734 | C25: RA222755 REX 219254C001 RA192437 | G25: 0.33333333 | H25: 0.52083333 | I25: 0.55208333 | J25: 0.72847222 | M25: =(F25-E25)+(L25-K25) -> 0 | N25: =(H25-G25) -> 0.1875 | O25: =(J25-I25) -> 0.17638889 | P25: =SUM(M25:O40) -> 0.36388889 | R25: RA222755 | S25: (1h00)
S26: JIANGSU
S27: Relancer ATOS pour le doc 24HCC | V27: ok.Done
R28: REX | S28: (2h30)
S29: ALSYMEX | T29: ok.Done
R30: 219254C001 | S30: (2h30)
S31: PADAH LNG
S32: Répondre à l'email d'ALSYMEX avec les moins values | V32: ok.Done
S33: Maj du plan 24PIDC21925401 | V33: ok.Done
T34: Répondre aux sstr:
U35: ACE (SDCL) | V35: LS_PSHC21925401-H-ACE | X35: In progress…
U36: ATOS (SDCL) | V36: LS_PSHC21925401-H-ATOS | X36: In progress…
R37: RA192437 | S37: (0h30)
S38: PIPECHINA_CNOOC
S39: Voir la vidéo du client pour le capteur de sélection du bras | W39: ok.Done
Q40: 0.29166667
A41: MERCREDI | B41: =SUM(B25+1) -> 45735 | C41: 219254C001 218020C001 214936C001 219124C001 | G41: 0.31944444 | H41: 0.52083333 | I41: 0.5625 | J41: 0.76388889 | M41: =(F41-E41)+(L41-K41) -> 0 | N41: =(H41-G41) -> 0.20138889 | O41: =(J41-I41) -> 0.20138889 | P41: =SUM(M41:O60) -> 0.40277778 | R41: 219254C001 | S41: (3h00)
S42: PADAH LNG
T43: Répondre aux sstr:
U44: ACE (SDCL) | V44: LS_PSHC21925401-H-ACE | X44: ok.Done | Y44: A vérifier avec JCP
U45: ATOS (SDCL) | V45: LS_PSHC21925401-H-ATOS | X45: ok.Done | Y45: A vérifier avec JCP
...

Sheet SEM13
A4: Nom: | B4: BELIN brice
A5: semaine 13 | B5: du | C5: =SUM('SEM12'!B114+1) -> 45740 | D5: au | E5: =SUM(B102) -> 45746
E6: Route | F6: aller | G6: Client ou usine | I6: Client ou usine | K6: Route retour | M6: TOTAL | Q6: potentiel jour
A7: Jour | B7: Date | C7: Nom client ou usine | E7: Heure départ | F7: Heure arrivée | G7: Heure arrivée | H7: Heure départ | I7: Heure arrivée | J7: Heure départ | K7: Heure départ | L7: Heure arrivée | M7: Heure route | N7: Heure client | O7: Heure usine | P7: Général
A9: LUNDI | B9: =SUM(C5) -> 45740 | C9: 219254C001 RA172190 214936C001 | G9: 0.35625 | H9: 0.52430556 | I9: 0.57291667 | J9: 0.72916667 | M9: =(F26-E26)+(L26-K26) -> 0 | N9: =(H9-G9) -> 0.16805556 | O9: =(J9-I9) -> 0.15625 | P9: =SUM(M9:O26) -> 0.32430556 | R9: 219254C001 | S9: (2h30)
S10: PADAH LNG
S11: Maj pour les plans ci-dessous:
T12: UCL | U12: LS_UCLC21925401 | V12: In progress… | W12: En attente retour de Karim | Y12: Valider avec JCP la qualité du N2 à utiliser
T13: CSA | U13: 24CSAC21925401 | V13: In progress…
T14: Interco | U14: 24EIDC21925401 | V14: In progress…
R15: RA172190 | S15: (4h00)
S16: HOEGH
T17: Meeting avec JCP | V17: ok.Done
T18: Ajouter les longueurs de chaque câble dans l'interco | W18: ok.Done | X18: A VALIDER AVEC JCP
T19: Mettre à jour l'interco + longueur BOM | W19: In progress…
R20: 214936C001 | S20: (1h00)
S21: WISON
S22: Envoyer la CRS pour le plan LS_UCL | V22: ok.Done
S23: Maj du plan ci-dessous:
T24: HMI | U24: LS_HMIC21493601 | V24: ok.Done | W24: (suite retour commentaires client)
Q26: 0.29166667
A27: MARDI | B27: =SUM(B9+1) -> 45741 | C27: 219254C001 RA172190 214936C001 Objectifs 2025 | G27: 0.32777778 | H27: 0.52083333 | I27: 0.55208333 | J27: 0.70833333 | M27: =(F48-E48)+(L48-K48) -> 0 | N27: =(H27-G27) -> 0.19305556 | O27: =(J27-I27) -> 0.15625 | P27: =SUM(M27:O48) -> 0.34930556 | R27: 219254C001 | S27: (4h30)
S28: PADAH LNG
S29: Maj pour les plans ci-dessous:
T30: UCL | U30: LS_UCLC21925401 | V30: ok.Done | W30: En attente retour de Karim | Y30: ECN: 1020924
T31: CSA | U31: 24CSAC21925401 | V31: In progress… | W31: ECN: 1020894
T32: Interco | U32: 24EIDC21925401 | V32: In progress… | W32: ECN: 102xxxx
S33: Lire les SDCLs ci-dessous:
T34: SDCL ATOS | U34: LS_PSHC21925401-H-Atos-rev3 | W34: ok.Done
T35: SDCL CORAIL | U35: LS_PSHC21925401-E-ASR-rev5 | W35: ok.Done
S36: Mag du DBI ci-dessous:
T37: PLC Cabinet | U37: 24134C21925402 | V37: ok.Done | W37: Ajouter le matériel Siemens dans la BOM
R39: RA172190 | S39: (1h30)
S40: HOEGH
T41: Meeting avec JCP | V41: ok.Done
T42: Ajouter les longueurs de chaque câble dans l'interco | W42: ok.Done | X42: A VALIDER AVEC JCP
T43: Mettre à jour l'interco + longueur BOM | W43: ok.Done
R44: Objectifs 2025 | S44: (1h00)
S45: Indiviuel & équipes
T46: Faire la proposition des objectifs à François PR. | W46: ok.Done
...

Sheet 1 TRIMESTRE
A1: BELIN Brice | B1: RECAPITULATIF 1ER TRIMESTRE 2020 | E1: 43928
A4: MOIS | B4: SEMAINE | C4: CLIENT / USINE | D4: NBRE HEURES
A6: JANVIER | B6: 1 | C6: usine | D6: ='SEM1'!N60 -> 0.077777778
B7: 2 | C7: usine | D7: ='SEM2'!N107 -> 0.23472222
B8: 3 | C8: usine | D8: ='SEM3'!N106 -> 0.12708333
B9: 4 | C9: usine | D9: ='SEM4'!N113 -> 0.13333333
A10: FEVRIER | B10: 5 | C10: usine | D10: ='SEM5'!N121 -> 0.19861111
B11: 6 | C11: usine | D11: ='SEM6'!N115 -> 0.20763889
B12: 7 | C12: usine | D12: ='SEM7'!N102 -> 0.17708333
B13: 8 | C13: usine | D13: ='SEM8'!N150 -> 0.15
A14: MARS | B14: 9 | C14: usine | D14: ='SEM9'!N104 -> 0.17986111
B15: 10 | C15: usine | D15: ='SEM10'!N94 -> 0.15486111
B16: 11 | C16: usine | D16: ='SEM11'!N121 -> 0.24722222
B17: 12 | C17: usine | D17: ='SEM12'!N118 -> 0.25277778
B18: 13 | C18: usine | D18: ='SEM13'!N106 -> 0.49375
C26: TOTAL | D26: =SUM(D6:D24) -> 2.6347222

Sheet SEM14 
A4: Nom: | B4: BELIN brice
A5: semaine 14 | B5: du | C5: =SUM('SEM13'!B102+1) -> 45747 | D5: au | E5: =SUM(B117) -> 45753
E6: Route | F6: aller | G6: Client ou usine | I6: Client ou usine | K6: Route retour | M6: TOTAL | Q6: potentiel jour
A7: Jour | B7: Date | C7: Nom client ou usine | E7: Heure départ | F7: Heure arrivée | G7: Heure arrivée | H7: Heure départ | I7: Heure arrivée | J7: Heure départ | K7: Heure départ | L7: Heure arrivée | M7: Heure route | N7: Heure client | O7: Heure usine | P7: Général
A9: LUNDI | B9: =SUM(C5) -> 45747 | C9: RA192454 219254C001 218972C001 218020C001 | G9: 0.36041667 | H9: 0.52083333 | I9: 0.56944444 | J9: 0.72916667 | M9: =(F26-E26)+(L26-K26) -> 0 | N9: =(H9-G9) -> 0.16041667 | O9: =(J9-I9) -> 0.15972222 | P9: =SUM(M9:O26) -> 0.32013889 | R9: RA192454 | S9: (1h30)
S10: TORTUE
S11: Pb de CPMS | T11: Investigation en cours… | V11: ok.Done
S12: Meeting avec le client | V12: In progress…
R13: 219254C001 | S13: (4h30)
S14: PADAH LNG
S15: Maj pour les plans ci-dessous:
T16: Interco | U16: 24EIDC21925401 | V16: In progress… | W16: ECN: 1021126
T17: E&H on Dock | U17: 24125C21925401 | V17: ok.Done | W17: ok - Mettre à jour
S18: Prépare la spec | T18: PSH | U18: LS_PSHC219254 | V18: In progress… | W18: (pour ACE)
R19: 218972C001 | S19: (1h00)
S20: ENERGIA COSTA AZUL
S21: Mettre le plan LCP sur ARAS | U21: 2413416207701 | V21: Rev6 | W21: ok.Done
S22: En attente des sources de la part d'ALSYMEX | V22: ok.Done
R23: 218020C001 | S23: (0h30)
S24: TCC
S25: Répondre à l'email de Mr Airoldi (ATOS) | V25: ok.Done
Q26: 0.29166667
A27: MARDI | B27: =SUM(B9+1) -> 45748 | C27: 219254C001 214936C001 219453C001 218972C001 | G27: 0.33055556 | H27: 0.52083333 | I27: 0.58333333 | J27: 0.72916667 | M27: =(F43-E43)+(L43-K43) -> 0 | N27: =(H27-G27) -> 0.19027778 | O27: =(J27-I27) -> 0.14583333 | P27: =SUM(M27:O43) -> 0.33611111 | R27: 219254C001 | S27: (5h30)
S28: PADAH LNG
S29: Lire et corrigé le LS_DDS pour le BE MECA | V29: ok.Done
S30: Prépare la spec | T30: PSH | U30: LS_PSHC219254 | V30: In progress… | W30: En attente retour SDCL ACE
S31: Maj pour les plans ci-dessous:
T32: Interco | U32: 24EIDC21925401 | V32: In progress… | W32: ECN: 1021126
R33: 214936C001 | S33: (0h30)
S34: WISON
S35: Faire email pour demander les derniers sourcs du doc "Hydraulic Package 3D" | X35: ok.Done | Y35: En attente retour Doc Ctrl
R36: 219453C001 | S36: (0h30)
S37: COIGN
S38: Meeting avec PM / Alsymex pour comment solutionner la demande du client | W38: ok.Done
R39: 218972C001 | S39: (0h30)
S40: COSTA AZUL
S41: Maj du DBI:
T42: radio | U42: 2489935C21897201P | V42: ok.Done
Q43: 0.29166667
A44: MERCREDI | B44: =SUM(B27+1) -> 45749 | C44: 219254C001 219453C001 219030C001 | G44: 0.30625 | H44: 0.5 | I44: 0.5625 | J44: 0.75555556 | M44: =(F60-E60)+(L60-K60) -> 0 | N44: =(H44-G44) -> 0.19375 | O44: =(J44-I44) -> 0.19305556 | P44: =SUM(M44:O60) -> 0.38680556 | R44: 219254C001 | S44: (4h00)
...

Sheet SEM15
A4: Nom: | B4: BELIN brice
A5: semaine 15 | B5: du | C5: =SUM('SEM14 '!B117+1) -> 45754 | D5: au | E5: =SUM(B105) -> 45760
E6: Route | F6: aller | G6: Client ou usine | I6: Client ou usine | K6: Route retour | M6: TOTAL | Q6: potentiel jour
A7: Jour | B7: Date | C7: Nom client ou usine | E7: Heure départ | F7: Heure arrivée | G7: Heure arrivée | H7: Heure départ | I7: Heure arrivée | J7: Heure départ | K7: Heure départ | L7: Heure arrivée | M7: Heure route | N7: Heure client | O7: Heure usine | P7: Général
A9: LUNDI | B9: =SUM(C5) -> 45754 | C9: OS172220 ITS CS 219254C001 219030C001 CONDUCTIX 219124C001 | G9: 0.35833333 | H9: 0.5 | I9: 0.5625 | J9: 0.71875 | M9: =(F41-E41)+(L41-K41) -> 0 | N9: =(H9-G9) -> 0.14166667 | O9: =(J9-I9) -> 0.15625 | P9: =SUM(M9:O41) -> 0.29791667 | R9: OS172220 | S9: (0h30)
S10: ENI CORAL
S11: Mettre sur ARAS les sources des docs ci-dessous:
T12: Pipe tags | U12: 33899172220011 | W12: ok.Done | X12: Vérifiez avec le PDF dans ARAS
T13: Pipe tags | U13: 33899172220012 | W13: ok.Done | X13: Vérifiez avec le PDF dans ARAS
T14: Pipe tags | U14: 33899172220013 | W14: ok.Done | X14: Vérifiez avec le PDF dans ARAS
R15: ITS CS | S15: (0h30)
S16: Mettre les heures de la sem 14 | U16: ok.Done
R17: 219254C001 | S17: (0h30)
S18: PADAH LNG
S19: Mettre sur ARAS le plan ci-dessous:
T20: E&H on Dock | U20: 24125C21925401 | W20: ok.Done
R21: 219030C001 | S21: (1h30)
S22: TAL OIL
S23: Mettre sur ARAS les plans ci-dessous:
T24: LCP Berth 1 | U24: 2413403364301 | W24: ok.Done | X24: En atente de réception ALSYMEX
T25: ECD Berth 1 | U25: 2403003364301 | W25: ok.Done | X25: En atente de réception ALSYMEX
S26: Envoyer email à ALSYMEX | U26: ok.Done
R27: 214365C001 | S27: (1h30)
S28: TR
S29: Répondre email de ACTEMIUM | U29: ok.Done
R30: CONDUCTIX | S30: (2h00)
S31: Revoir les PNS à créer dans ARAS suite à la réunion avec CONDUCTIX | X31: ok.Done
S32: Maj de la feuille excel + soumettre à JCP | V32: ok.Done | W32: En attente de validation avec François / JCP
R33: 219124C001 | S33: (1h00)
S34: ARAMCO
S35: Maj des plans SVA & HPU
T36: SVA - B17 | U36: 24133C21912401 | W36: ECN: 1021179 | X36: ok.Done | Y36: rajouter NMR601 sur toutes les pages
T37: HPU - B17 | U37: 24136C21912401 | W37: ECN: 1021179 | X37: ok.Done | Y37: Déjà sur le plan….En attente de retour du Doc Ctrl
T38: SVA - B18 | U38: 24133C21912402 | W38: ECN: 1021179 | X38: ok.Done | Y38: ok. Renvoyer l'ECN à Delphine
T39: HPU - B18 | U39: 24136C21912402 | W39: ECN: 1021179 | X39: ok.Done
Q41: 0.29166667
A42: MARDI | B42: =SUM(B9+1) -> 45755 | C42: 214365C001 214936C001 219124C001 | G42: 0.32708333 | H42: 0.52083333 | I42: 0.55208333 | J42: 0.71041667 | M42: =(F42-E42)+(L42-K42) -> 0 | N42: =(H42-G42) -> 0.19375 | O42: =(J42-I42) -> 0.15833333 | P42: =SUM(M42:O60) -> 0.35208333 | R42: 214936C001 | S42: (2h00)
S43: WISON
S44: Mettre à jour le plan ci-dessous:
T45: Hydraulic 3D | U45: 33028C21493601_3D | X45: ok.Done | Y45: En attente de Mathieu pour envoi
...

Sheet SEM16
A4: Nom: | B4: BELIN brice
A5: semaine 16 | B5: du | C5: =SUM('SEM15'!B105+1) -> 45761 | D5: au | E5: =SUM(B126) -> 45767
E6: Route | F6: aller | G6: Client ou usine | I6: Client ou usine | K6: Route retour | M6: TOTAL | Q6: potentiel jour
A7: Jour | B7: Date | C7: Nom client ou usine | E7: Heure départ | F7: Heure arrivée | G7: Heure arrivée | H7: Heure départ | I7: Heure arrivée | J7: Heure départ | K7: Heure départ | L7: Heure arrivée | M7: Heure route | N7: Heure client | O7: Heure usine | P7: Général
A9: LUNDI | B9: =SUM(C5) -> 45761 | C9: 214365C001 RA212635 219030C001 219453C001 219047C001 RA172190 218614C001 | G9: 0.35486111 | H9: 0.52083333 | I9: 0.54166667 | J9: 0.64652778 | M9: =(F9-E9)+(L9-K9) -> 0 | N9: =(H9-G9) -> 0.16597222 | O9: =(J9-I9) -> 0.10486111 | P9: =SUM(M9:O38) -> 0.27083333 | R9: 214365C001 | S9: (0h30)
S10: TR
S11: Lire email de Delphine | V11: ok.Done
R12: RA212635 | S12: (0h30)
S13: CPC TAINCHUNG
S14: Répondre à ACTEMIUM | V14: ok.Done
R15: 219030C001 | S15: (0h30)
S16: TAL OIL
S17: Transférer l'email du client à ALSYMEX | V17: ok.Done
R18: 219453C001 | S18: (3h00)
S19: COIGN
S20: Envoyer les plans ci-dessous:
T21: CPMS+ paramétrages à ALSYMEX | W21: ok.Done
R22: 219047C001 | S22: (1h00)
S23: CHEVRON
S24: Mettre sur ARS le plan ci-dessous:
T25: PLC assembly | V25: 24134121713022 | X25: ok.Done
S26: Mettre à jour les DBIs ci-dessous:
V27: 248993512138P | X27: ok.Done
V28: 248993512139P | X28: ok.Done
R29: RA172190 | S29: (0h30)
S30: HOEGH
S31: Faire email à ACE pour les sources des plans ci-dessous:
T32: HPU | U32: 2413617219001 | W32: In progress… | X32: En attente retour ACE
T33: ERS Accu | U33: 2414117219001 | W33: In progress… | X33: En attente retour ACE
R34: 218614C001 | S34: (1h00)
S35: ENERGOS ESKIMO
S36: Investigation problèmes de valeurs entre STAHL display & CPMS+ display | Y36: In progress…
Q38: 0.29166667
A39: MARDI | B39: =SUM(B9+1) -> 45762 | C39: 218614C001 RA172190 RA212635 219712C001 219867C001 | G39: 0.33125 | H39: 0.52083333 | I39: 0.54166667 | J39: 0.7375 | M39: =(F59-E59)+(L59-K59) -> 0 | N39: =(H39-G39) -> 0.18958333 | O39: =(J39-I39) -> 0.19583333 | P39: =SUM(M39:O59) -> 0.38541667 | R39: 218614C001 | S39: (1h00)
S40: ENERGOS ESKIMO
S41: Investigation problèmes de valeurs entre STAHL display & CPMS+ display | Y41: In progress…
S42: Appelez Alsymex (Berger pour avis)
R43: RA172190 | S43: (0h30)
S44: HOEGH
S45: Faire email à ACE pour les sources des plans ci-dessous:
...

Sheet SEM17
A4: Nom: | B4: BELIN brice
A5: semaine 17 | B5: du | C5: =SUM('SEM16'!B126+1) -> 45768 | D5: au | E5: =SUM(B59) -> 45774
E6: Route | F6: aller | G6: Client ou usine | I6: Client ou usine | K6: Route retour | M6: TOTAL | Q6: potentiel jour
A7: Jour | B7: Date | C7: Nom client ou usine | E7: Heure départ | F7: Heure arrivée | G7: Heure arrivée | H7: Heure départ | I7: Heure arrivée | J7: Heure départ | K7: Heure départ | L7: Heure arrivée | M7: Heure route | N7: Heure client | O7: Heure usine | P7: Général
A9: LUNDI | B9: =SUM(C5) -> 45768 | C9: FERIE | G9: 0 | H9: 0 | I9: 0 | J9: 0 | M9: =(F11-E11)+(L11-K11) -> 0 | N9: =(H9-G9) -> 0 | O9: =(J9-I9) -> 0 | P9: =SUM(M9:O11) -> 0
Q11: 0
A12: MARDI | B12: =SUM(B9+1) -> 45769 | C12: 218020C001 219712C001 | G12: 0.32916667 | H12: 0.52083333 | I12: 0.54166667 | J12: 0.73611111 | M12: =(F24-E24)+(L24-K24) -> 0 | N12: =(H12-G12) -> 0.19166667 | O12: =(J12-I12) -> 0.19444444 | P12: =SUM(M12:O24) -> 0.38611111 | R12: 218020C001
S13: TCC
S14: Editer les documents ci-dessous:
T15: FAT élec
T16: FAT Hydro
R17: 219712C001 | S17: (7h00)
S18: TECHEAST
S19: Editer le plan ci-dessous:
T20: EID | U20: 24EIDC21971201 | W20: Rev0 | X20: ok.Done | Y20: En attentre validation avec JCP
T21: HCD | U21: 24EHCD21971201 | W21: Rev0 | X21: ok.Done | Y21: maj suite validation JCP
T22: IOL | U22: LS_IOLC21971201 | W22: Rev0 | X22: ok.Done
Q24: 0.29166667
A25: MERCREDI | B25: =SUM(B12+1) -> 45770 | C25: 219712C001 | G25: 0.30069444 | H25: 0.52083333 | I25: 0.55208333 | J25: 0.72708333 | M25: =(F31-E31)+(L31-K31) -> 0 | N25: =(H25-G25) -> 0.22013889 | O25: =(J25-I25) -> 0.175 | P25: =SUM(M25:O31) -> 0.39513889 | R25: 219712C001 | S25: (7h00)
S26: TECHEAST
S27: Editer le plan ci-dessous:
T28: Motor Starter | U28: 24MSDC21971201 | W28: Rev0 | X28: ok.Done
S29: Préparer les DBIs pour LP en élec | V29: ok.Done
S30: Faire le LP | T30: ok.Done
Q31: 0.29166667
A32: JEUDI | B32: =SUM(B25+1) -> 45771 | C32: 219712C001 219453C001 | G32: 0.35625 | H32: 0.52083333 | I32: 0.5625 | J32: 0.73611111 | M32: =(F53-E53)+(L53-K53) -> 0 | N32: =(H32-G32) -> 0.16458333 | O32: =(J32-I32) -> 0.17361111 | P32: =SUM(M32:O53) -> 0.33819444 | R32: 219712C001 | S32: (1h00)
S33: TECHEAST
S34: Mettre les plans ci-dessous sur ARAS:
T35: HCD | U35: 24EHCD21971201 | W35: Rev0 | X35: ok.Done
T36: CSA | U36: 24CSAC21971201 | W36: Rev0 | X36: ok.Done
T37: EID | U37: 24EIDC21971201 | W37: Rev0 | X37: ok.Done
T38: IOL | U38: LS_IOLC21971201 | W38: Rev0 | X38: ok.Done
S39: Editer le plan ci-dessous:
T40: CND | U40: LS_CNDC21971201 | W40: Rev0 | X40: ok.Done
R42: 219453C001 | S42: (0h30)
S43: COIGN
S44: Envoyer email à Arnaud pour confirmation date du certificat e conformité | Y44: ok.Done
R45: 219867C001 | S45: (2h00)
S46: MARSA
S47: Préparer les DBIs sur ARAS | V47: ok.Done | W47: En attente validation Julien R
...

Sheet SEM18
A4: Nom: | B4: BELIN brice
A5: semaine 18 | B5: du | C5: =SUM('SEM17'!B59+1) -> 45775 | D5: au | E5: =SUM(B25) -> 45781
E6: Route | F6: aller | G6: Client ou usine | I6: Client ou usine | K6: Route retour | M6: TOTAL | Q6: potentiel jour
A7: Jour | B7: Date | C7: Nom client ou usine | E7: Heure départ | F7: Heure arrivée | G7: Heure arrivée | H7: Heure départ | I7: Heure arrivée | J7: Heure départ | K7: Heure départ | L7: Heure arrivée | M7: Heure route | N7: Heure client | O7: Heure usine | P7: Général
A9: LUNDI | B9: =SUM(C5) -> 45775 | C9: CP | G9: 0 | H9: 0 | I9: 0 | J9: 0 | M9: =(F11-E11)+(L11-K11) -> 0 | N9: =(H9-G9) -> 0 | O9: =(J9-I9) -> 0 | P9: =SUM(M9:O11) -> 0
Q11: 0
A12: MARDI | B12: =SUM(B9+1) -> 45776 | C12: CP | G12: 0 | H12: 0 | I12: 0 | J12: 0 | M12: =(F14-E14)+(L14-K14) -> 0 | N12: =(H12-G12) -> 0 | O12: =(J12-I12) -> 0 | P12: =SUM(M12:O14) -> 0
Q14: 0
A15: MERCREDI | B15: =SUM(B12+1) -> 45777 | C15: CP | G15: 0 | H15: 0 | I15: 0 | J15: 0 | M15: =(F17-E17)+(L17-K17) -> 0 | N15: =(H15-G15) -> 0 | O15: =(J15-I15) -> 0 | P15: =SUM(M15:O17) -> 0
Q17: 0
A18: JEUDI | B18: =SUM(B15+1) -> 45778 | C18: FERIE | G18: 0 | H18: 0 | I18: 0 | J18: 0 | M18: =(F20-E20)+(L20-K20) -> 0 | N18: =(H18-G18) -> 0 | O18: =(J18-I18) -> 0 | P18: =SUM(M18:O20) -> 0
Q20: 0
A21: VENDREDI | B21: =SUM(B18+1) -> 45779 | C21: CP | G21: 0 | H21: 0 | I21: 0 | J21: 0 | M21: =(F23-E23)+(L23-K23) -> 0 | N21: =(H21-G21) -> 0 | O21: =(J21-I21) -> 0 | P21: =SUM(M21:O23) -> 0
Q23: 0
A24: SAMEDI | B24: =SUM(B21+1) -> 45780 | M24: =(F25-E25)+(H25-G25) -> 0 | N24: =(G25-F25)+(I25-H25) -> 0 | O24: =(H25-G25)+(J25-I25) -> 0 | P24: =(I25-H25)+(K25-J25) -> 0
A25: DIMANCHE | B25: =SUM(B24+1) -> 45781
J27: TOTAL TRAVAILLE | M27: =SUM(M9+M12+M15+M18+M21+M24+M25) -> 0 | N27: =SUM(N9+N12+N15+N18+N21+N24+N25) -> 0 | O27: =SUM(O9+O12+O15+O18+O21+O24+O25) -> 0 | P27: =SUM(P9+P12+P15+P18+P21+P24+P25) -> 0
J28: POTENTIEL SEMAINE | N28: =SUM(Q9:Q25) -> 0
J29: TOTAL SEMAINE HS | N29: =SUM(P27-N28) -> 0
J30: TOTAL PRECEDENT HS | N30: ='SEM17'!N65 -> 0.68472222
J31: NOUVEAU TOTAL HS | N31: =N29+N30 -> 0.68472222

Sheet SEM19
A4: Nom: | B4: BELIN brice
A5: semaine 19 | B5: du | C5: =SUM('SEM18'!B25+1) -> 45782 | D5: au | E5: =SUM(B97) -> 45788
E6: Route | F6: aller | G6: Client ou usine | I6: Client ou usine | K6: Route retour | M6: TOTAL | Q6: potentiel jour
A7: Jour | B7: Date | C7: Nom client ou usine | E7: Heure départ | F7: Heure arrivée | G7: Heure arrivée | H7: Heure départ | I7: Heure arrivée | J7: Heure départ | K7: Heure départ | L7: Heure arrivée | M7: Heure route | N7: Heure client | O7: Heure usine | P7: Général
A9: LUNDI | B9: =SUM(C5) -> 45782 | C9: 219254C001 218020C001 219712C001 | G9: 0.35416667 | H9: 0.52083333 | I9: 0.5625 | J9: 0.72986111 | M9: =(F36-E36)+(L36-K36) -> 0 | N9: =(H9-G9) -> 0.16666667 | O9: =(J9-I9) -> 0.16736111 | P9: =SUM(M9:O36) -> 0.33402778 | R9: 219254C001 | S9: (3h00)
S10: PADAH LNG
S11: Répondre email de Corail | U11: ok.Done
S12: Reprendre la BJ pied de bras - Hauteur 200 mm | W12: ok.Done | X12: A VALIDER PAR JCP
S13: Mettre la plan ci-dessous sur ARAS:
T14: ECD | U14: 24ECDC21925401 | W14: ok.Done | X14: ECN nr: | Y14: 1021678 | Z14: En attente validation par Doc Ctrl
R21: 218020C001 | S21: (3h00)
S22: TCC
S23: Maj des DBIs ci-dessous:
T24: Radio | U24: 2489935C2180201P | W24: ok.Done
T25: PC Maint. | U25: 24899C21802002 | W25: ok.Done
T26: Superv. | U26: 24899C21802001 | W26: ok.Done
T27: Spare part | U27: 24172C2180203A | W27: ok.Done
T28: PLC Cab. | U28: 24134C21802002 | W28: ok.Done
S29: Maj des DBIs dans ARAS | U29: ok.Done | V29: ECN nr: | W29: 1021752 | X29: En attente validation par Wael - OK
S30: Maj des paramètres CPMS+ | U30: ok.Done
R31: 219712C001 | S31: (0h30)
S32: TECHEAST
S33: Envoyer le doc IOL à Laurent Rozier | W33: ok.Done
S34: Edition du doc:
T35: Elec FAT P. | U35: LS_EFPC219871201 | W35: ok.Done | X35: A VALIDER PAR JCP
Q36: 0.29166667
A37: MARDI | B37: =SUM(B9+1) -> 45783 | C37: 219712C001 219867C001 219204C001 | G37: 0.32638889 | H37: 0.52083333 | I37: 0.55208333 | J37: 0.75208333 | M37: =(F51-E51)+(L51-K51) -> 0 | N37: =(H37-G37) -> 0.19444444 | O37: =(J37-I37) -> 0.2 | P37: =SUM(M37:O51) -> 0.39444444 | R37: 219712C001 | S37: (5h30)
S38: TECHEAST
S39: Edition du doc ci-dessous:
T40: IOL | U40: LS_IOLC21971201 | W40: ok.Done
S41: Maj du CND après commentaires JCP | V41: ok.Done | W41: ECN nr: | X41: 1021787 | Y41: En attente validation Doc CTRL
S42: Maj du plan EID | V42: ok.Done
R43: 219867C001 | S43: (1h00)
S44: MARSA LNG
S45: Edition du plan ci-dessous:
T46: PID | U46: 24PIDC21986701 | W46: In progress…
R47: 219204C001 | S47: (0h30)
S48: ARAMCO
S49: Mettre le plan ci-dessous sur ARAS:
T50: Remote Panel | U50: 2413918224701 | W50: ok.Done
...

Sheet SEM20
A4: Nom: | B4: BELIN brice
A5: semaine 20 | B5: du | C5: =SUM('SEM19'!B97+1) -> 45789 | D5: au | E5: =SUM(B73) -> 45795
E6: Route | F6: aller | G6: Client ou usine | I6: Client ou usine | K6: Route retour | M6: TOTAL | Q6: potentiel jour
A7: Jour | B7: Date | C7: Nom client ou usine | E7: Heure départ | F7: Heure arrivée | G7: Heure arrivée | H7: Heure départ | I7: Heure arrivée | J7: Heure départ | K7: Heure départ | L7: Heure arrivée | M7: Heure route | N7: Heure client | O7: Heure usine | P7: Général
A9: LUNDI | B9: =SUM(C5) -> 45789 | C9: 218020C001 219712C001 | E9: 0.4375 | F9: 0.75 | G9: 0.35902778 | H9: 0.4375 | I9: 0.71875 | J9: 0.77083333 | K9: 0 | L9: 0 | M9: =(F9-E9)+(L9-K9) -> 0.3125 | N9: =(H9-G9) -> 0.078472222 | O9: =(J9-I9) -> 0.052083333 | P9: =SUM(M9:O21) -> 0.44305556 | R9: 219712C001 | S9: (2h00)
S10: TECHEAST
S11: Mettre la SDCL ACTEMIUM dans le projet | W11: ok.Done
R13: 218020C001 | S13: (7h00)
S14: TCC
S15: Route aller chez ACTEMIUM | U15: ok.Done
Q21: 0.29166667
A22: MARDI | B22: =SUM(B9+1) -> 45790 | C22: FAT ELEC 218020C001 | E22: 0.33333333 | F22: 0.33611111 | G22: 0.33611111 | H22: 0.52083333 | I22: 0.5625 | J22: 0.80208333 | K22: 0.75 | L22: 0.77083333 | M22: =(F22-E22)+(L22-K22) -> 0.023611111 | N22: =(H22-G22) -> 0.18472222 | O22: =(J22-I22) -> 0.23958333 | P22: =SUM(M22:O27) -> 0.44791667 | R22: 218020C001
S23: TCC
S24: FAT électrique chez ACTEMIUM | U24: ok.Done
Q27: 0.29166667
A28: MERCREDI | B28: =SUM(B22+1) -> 45791 | C28: FAT ELEC 218020C001 | E28: 0 | F28: 0 | G28: 0 | H28: 0 | I28: 0.5625 | J28: 0.72430556 | K28: 0.33333333 | L28: 0.60416667 | M28: =(F28-E28)+(L28-K28) -> 0.27083333 | N28: =(H28-G28) -> 0 | O28: =(J28-I28) -> 0.16180556 | P28: =SUM(M28:O36) -> 0.43263889 | R28: 218020C001
S29: TCC
S30: Retour de chez ACTEMIUM | U30: ok.Done
R31: 219712C001
S32: TECHEAST
S33: Répondre sur la SDCL Rev1 ACE | V33: ok.Done
S34: Répondre sur la SDCL Rev1 ATOS | V34: ok.Done
Q36: 0.29166667
A37: JEUDI | B37: =SUM(B28+1) -> 45792 | C37: 218020C001 219712C001 213996C001 | G37: 0.35902778 | H37: 0.52083333 | I37: 0.55208333 | J37: 0.70069444 | M37: =(F54-E54)+(L54-K54) -> 0 | N37: =(H37-G37) -> 0.16180556 | O37: =(J37-I37) -> 0.14861111 | P37: =SUM(M37:O54) -> 0.31041667 | R37: 219712C001 | S37: (1h00)
S38: TECHEAST
S39: Répondre sur la SDCL Rev 3 ACE | V39: ok.Done
S40: Régarder le retour d'ATOS sur la SDCL | V40: In progress…
R41: 218020C001 | S41: (3h00)
S42: Scanner le rapport de FAT | V42: ok.Done
S43: Le renvoyer à ACTEMIUM & Inspecteur TALABARDON | W43: ok.Done
S44: Copier les éléments ci-dessous sur le sharepoint 218020C001 TCC/ACTEMIUM/FAT:
T45: FAT Report | U45: LS_EFPC21802001 | W45: ok.Done
T46: ITP | U46: LS_ITPC2180200 | W46: ok.Done
T47: Etal. Multi. | W47: ok.Done
T48: Photos LCP & PLCC | W48: ok.Done
T49: Certificats IECEX, CCC, peinture | W49: ok.Done
S50: Faire la NDF | T50: In progress… | U50: En attente de validation Manager
R51: 213996C001 | S51: (1h00)
S52: PLAQUEMINES
S53: Conf call pour problème de radio sur site | V53: ok.Done
...

Sheet SEM21
A4: Nom: | B4: BELIN brice
A5: semaine 21 | B5: du | C5: =SUM('SEM20'!B73+1) -> 45796 | D5: au | E5: =SUM(B108) -> 45802
E6: Route | F6: aller | G6: Client ou usine | I6: Client ou usine | K6: Route retour | M6: TOTAL | Q6: potentiel jour
A7: Jour | B7: Date | C7: Nom client ou usine | E7: Heure départ | F7: Heure arrivée | G7: Heure arrivée | H7: Heure départ | I7: Heure arrivée | J7: Heure départ | K7: Heure départ | L7: Heure arrivée | M7: Heure route | N7: Heure client | O7: Heure usine | P7: Général
A9: LUNDI | B9: =SUM(C5) -> 45796 | C9: 213996C001 Meeting RA192454 IQ 219254C001 219867C001 219712C001 | G9: 0.35555556 | H9: 0.5 | I9: 0.56944444 | J9: 0.72847222 | M9: =(F9-E9)+(L9-K9) -> 0 | N9: =(H9-G9) -> 0.14444444 | O9: =(J9-I9) -> 0.15902778 | P9: =SUM(M9:O35) -> 0.30347222 | R9: 213996C001 | S9: (1h00)
S10: Plaquemines
S11: Problème de mvt d'un bras sur la jetée 1 sans utiliser la radio | X11: ok.Done
R12: Meeting | S12: (0h30)
S13: Meeting sur les projets avec JCP / Wael | W13: ok.Done
R14: RA192454 | S14: (0h30)
S15: BP TORTUE
S16: Aide au Support Line TEN | V16: ok.Done
R17: IQ | S17: (0h30)
S18: Meeting avec Doc Control | V18: ok.Done
R19: 219867C001 | S19: (0h30)
S20: MARSA
S21: Remplir la VDL avec les informations manquantes | W21: In progress… | X21: A REMPLIR AVEC JCP
R22: 219254C001 | S22: (1h00)
S23: PADAH LNG
T24: Meeting avec JCP | V24: ok.Done
T25: Meeting avec BE Meca | V25: ok.Done
R26: 219712C001 | S26: (3h00)
S27: TECHEAST
T28: Répondre à la SDCL d'ACTEMIUM | W28: ok.Done
T29: Editer le doc LS_PSEC21971201 Rev1 pour ALSYMEX | X29: ok.Done
T30: Maj du DBI ci-dessous:
U31: LCP | V31: 24134C21971201 | X31: ok.Done | Y31: ECN nr: | Z31: 1022029
T32: Editer email Class1 | V32: ok.Done
T33: Finir le plan ci-dessous:
U34: EOA | V34: 24EOAC21971201 | X34: In progress… | Y34: Finit le tableau de nomenclature
Q35: 0.29166667
A36: MARDI | B36: =SUM(B9+1) -> 45797 | C36: 219712C001 219254C001 RA172190 Projets 214365C001 | G36: 0.32777778 | H36: 0.52083333 | I36: 0.55208333 | J36: 0.72916667 | M36: =(F36-E36)+(L36-K36) -> 0 | N36: =(H36-G36) -> 0.19305556 | O36: =(J36-I36) -> 0.17708333 | P36: =SUM(M36:O60) -> 0.37013889 | R36: 219712C001 | S36: (3h30)
S37: TECHEAST
T38: Finir le plan ci-dessous:
U39: EOA | V39: 24EOAC21971201 | X39: In progress…
T40: Création du kit H&E MLA-1 & 2 | V40: 248990821971221 | X40: ok.Done | Y40: Status | Z40: PRELIMINARY
T41: Création de la spec LS_TAGLIST | V41: LS_TAGLISTC21971201 | X41: ok.Done | Y41: Status | Z41: RELEASED
T42: Création de la BJ Embase (7P) | V42: 24JBDC21634001 | X42: ok.Done | Y42: ECN nr: | Z42: 1022046 | AA42: EN ATTENTE VALIDATION WAEL
U43: création de la spec | W43: LS_JBSC21971201 | Y43: ok.Done
T44: Création des spare parts | X44: ok.Done
...

Sheet SEM22
A4: Nom: | B4: BELIN brice
A5: semaine 22 | B5: du | C5: =SUM('SEM21'!B108+1) -> 45803 | D5: au | E5: =SUM(B44) -> 45809
E6: Route | F6: aller | G6: Client ou usine | I6: Client ou usine | K6: Route retour | M6: TOTAL | Q6: potentiel jour
A7: Jour | B7: Date | C7: Nom client ou usine | E7: Heure départ | F7: Heure arrivée | G7: Heure arrivée | H7: Heure départ | I7: Heure arrivée | J7: Heure départ | K7: Heure départ | L7: Heure arrivée | M7: Heure route | N7: Heure client | O7: Heure usine | P7: Général
A9: LUNDI | B9: =SUM(C5) -> 45803 | C9: 219867C001 Mid Year Rev. 219254C001 220165c001 | G9: 0.35833333 | H9: 0.52083333 | I9: 0.55208333 | J9: 0.73333333 | M9: =(F25-E25)+(L25-K25) -> 0 | N9: =(H9-G9) -> 0.1625 | O9: =(J9-I9) -> 0.18125 | P9: =SUM(M9:O25) -> 0.34375 | R9: 219867C001 | S9: (5h30)
S10: MARSA
T11: Edition du plan:
